Workbook

Sheet Industrial Underwriting
B1: GTRE Industrial Underwriting Model — Ground-Up Development or Value-Add Acquisition
B2: Blue cells = your inputs (change these) Black cells = formulas (do not touch) Green cells = links from other tabs
B4: ① Property Overview
B5: Property Name | C5: [Enter Property Name]
B6: Deal Type | C6: [Select Deal Type]
B7: Submarket / Location | C7: [Enter Submarket]
B8: Building GSF
B9: Site Acreage
B10: Clear Height (ft)
B11: Land / Acquisition Cost
B12: Closing Date
B13: Hold Period (Years)
B14: Exit Cap Rate
B15: Disposition Cost %
B17: ② Development / Capital Budget
B18: Ground-up: enter full construction hard costs. Value-add: enter your renovation / capex budget here instead. Land / Acquisition Cost above covers either the land price or the purchase price.
B19: Hard Costs ($/SF of GSF)
B20: Total Hard Costs | C20: =C19*C8
B21: Soft Costs (% of Hard Costs)
B22: Total Soft Costs | C22: =C20*C21
B23: Contingency (% of Hard + Soft)
B24: Contingency $ | C24: =(C20+C22)*C23
B25: Total Project Cost | C25: =C11+C20+C22+C24
B27: ③ Tenant Roster (up to 4 tenants — leave rows blank if fewer)
B28: Tenant | C28: SF Leased | D28: Lease Start (Year #) | E28: Lease Term (Yrs) | F28: Base Rent ($/SF/Yr, NNN) | G28: Annual Escalation % | H28: TI Allowance ($/SF) | I28: Free Rent (Months, Yr 1)
B29: Tenant 1
B30: Tenant 2
B31: Tenant 3
B32: Tenant 4
B34: ④ Operations & Reimbursements
B35: Vacancy / Credit Loss %
B36: Non-Reimbursed Opex ($/SF/Yr)
B37: Management Fee (% of EGI)
B38: Expense Growth Rate
B40: ⑤ Construction / Renovation & Lease-Up Timing
B41: Construction / Renovation Duration (Months)
B42: Pre-Leased at Delivery? | C42: [Select]
B43: Months to Full Stabilization (if not pre-leased)
B45: ⑥ Financing
B46: Loan-to-Cost / Loan-to-Value
...

Sheet Exit Cap Sensitivity
B1: Exit Cap Rate Sensitivity
B2: Shows how sale price and the yield-on-cost-to-cap-rate spread move with the exit cap rate. Base case (column E) links to your assumption on the main tab.
B4: Scenario | C4: -100 bps | D4: -50 bps | E4: Base Case | F4: +50 bps | G4: +100 bps
B5: Exit Cap Rate | C5: ='Industrial Underwriting'!$C$14+(-0.01) | D5: ='Industrial Underwriting'!$C$14+(-0.005) | E5: ='Industrial Underwriting'!$C$14+(0) | F5: ='Industrial Underwriting'!$C$14+(0.005) | G5: ='Industrial Underwriting'!$C$14+(0.01)
B6: Implied Sale Price | C6: =(INDEX('Industrial Underwriting'!$D$68:$N$68,1,'Industrial Underwriting'!$C$13+2)/C5)*(1-'Industrial Underwriting'!$C$15) | D6: =(INDEX('Industrial Underwriting'!$D$68:$N$68,1,'Industrial Underwriting'!$C$13+2)/D5)*(1-'Industrial Underwriting'!$C$15) | E6: =(INDEX('Industrial Underwriting'!$D$68:$N$68,1,'Industrial Underwriting'!$C$13+2)/E5)*(1-'Industrial Underwriting'!$C$15) | F6: =(INDEX('Industrial Underwriting'!$D$68:$N$68,1,'Industrial Underwriting'!$C$13+2)/F5)*(1-'Industrial Underwriting'!$C$15) | G6: =(INDEX('Industrial Underwriting'!$D$68:$N$68,1,'Industrial Underwriting'!$C$13+2)/G5)*(1-'Industrial Underwriting'!$C$15)
B7: Yield-on-Cost vs. Cap Rate Spread | C7: ='Industrial Underwriting'!$C$77-C5 | D7: ='Industrial Underwriting'!$C$77-D5 | E7: ='Industrial Underwriting'!$C$77-E5 | F7: ='Industrial Underwriting'!$C$77-F5 | G7: ='Industrial Underwriting'!$C$77-G5
