Workbook
Name a: {"Client Name or Project Name"}
Name Architect: Summary!$E$36
Name Const_Mgmnt_Fees: Summary!$E$51
Name Development_Fees: Summary!$E$49
Name Engineering: Summary!$E$40
Name Environmental_Costs: Summary!$E$37
Name Equity_Provider: Summary!$D$68
Name FFE: Summary!$E$48
Name Financing_Costs: Summary!$E$43
Name Gurantee_Fees: Summary!$E$50
Name Hard_Costs: Summary!$E$53
Name HardCost_Conting: Summary!$E$54
Name Interest_Reserve: Summary!$E$45
Name IQ_CH: 110000
Name IQ_CQ: 5000
Name IQ_CY: 10000
Name IQ_DAILY: 500000
Name IQ_EXPENSE_CODE_: 9610001
Name IQ_FH: 100000
Name IQ_FQ: 500
Name IQ_FY: 1000
Name IQ_LTM: 2000
Name IQ_MONTH: 15000
Name IQ_NTM: 6000
Name IQ_WEEK: 50000
Name IQ_YTD: 3000
Name Land_Cost: Summary!$E$35
Name Legal_Closing: Summary!$E$41
Name Mezzanine_Provider: Summary!$D$69
Name Muni_Fees: Summary!$E$44
Name OneBROneBA_wtavg_SF: Summary!$D$25
Name ProjectName: {"Client Name or Project Name"}
Name SoftCost_Conting: Summary!$E$52
Name Soils_Testing: Summary!$E$39
Name SR_Loan_Provider: Summary!$D$70
Name Startup_Costs: Summary!$E$46
Name Studio_wtavg_SF: Summary!$D$24
Name Survey: Summary!$E$38
Name Taxes_Insurance: Summary!$E$42
Name ThreeBRThreeBA_wtavg_SF: Summary!$D$27
Name Total_Costs_Before_Mezz_Interest: Summary!$E$58
Name Total_Number_Units: Summary!$F$28
Name Total_Unit_wtavg_SF: Summary!$D$28
Name TwoBRTwoBA_wgtav: Summary!$D$26
Name Hard_Costs: #REF!
Name SoftCost_Conting: #REF!

Sheet Summary
B1: [Enter Property Name]
C2: [Enter Location]
A5: INPUT ASSUMPTIONS
B7: Product Type | D7: [Enter Product Type]
L8: MINIMUM MANAGEMENT FEE
B9: LEASE UP ASSUMPTIONS | F9: ABSORPTION SUMMARY | L9: MAXIMUM ANNUAL MANAGEMENT FEE
L10: DEV CO-INVEST
B11: RENTS CURRENT AS OF: | D11: - | F11: =Total_Number_Units | G11: TOTAL UNITS | L11: PREFERRED RETURN
B12: LAND CLOSING DATE: | G12: UNITS DELIVERED PER MONTH | L12: EXIT CAP RATE
B13: CLOSING/CONTRUCTION START: | D13: =D12 | G13: MONTHLY ABSORPTION | L13: CONST. LOAN BANK SPREAD
B14: MONTHS TO FIRST DELIVERY: | G14: WINTER MONTHLY ABSORPTION
B15: TOTAL MONTHS CONTRUCTION: | F15: =F13/F11 | G15: NET MONTHLY ABSORPTION (% TOTAL) | L15: MEZZ SWEEP? | M15: FALSE
B16: # MONTHS IN LEASE-UP | D16: =ROUNDUP((F11*F16)/F13,0) | G16: STABILIZED OCCUPANCY | L16: MEZZ LENDER ACCRUAL
B17: # MONTHS TO STABILIZATION: | D17: =D14+D16 | F17: =DATE(YEAR($D$13+(($D$14+$D$16)*30)), MONTH($D$13+(($D$14+$D$16)*30)), 15) | G17: PROPERTY STABILIZED | L17: MEZZ CURRENT PAY
G18: MONTHS CONCESSION DURING LEASEUP
B21: UNIT MIX
C23: BR / BA | D23: AVG. UNIT SF | E23: TOTAL SF | F23: UNITS | G23: % | H23: RENT PSF | I23: AVG. RENT
C24: ='Unit Mix'!B3 | D24: ='Unit Mix'!C3 | E24: =+D24*F24 | F24: ='Unit Mix'!D3 | G24: =IF(ISERROR(F24/$F$28),"",(F24/$F$28)) | H24: =IF(ISERROR(I24/D24),"",(I24/D24)) | I24: ='Unit Mix'!E3
C25: ='Unit Mix'!B4 | D25: ='Unit Mix'!C4 | E25: =+D25*F25 | F25: ='Unit Mix'!D4 | G25: =IF(ISERROR(F25/$F$28),"",(F25/$F$28)) | H25: =IF(ISERROR(I25/D25),"",(I25/D25)) | I25: ='Unit Mix'!E4
C26: ='Unit Mix'!B5 | D26: ='Unit Mix'!C5 | E26: =+D26*F26 | F26: ='Unit Mix'!D5 | G26: =IF(ISERROR(F26/$F$28),"",(F26/$F$28)) | H26: =IF(ISERROR(I26/D26),"",(I26/D26)) | I26: ='Unit Mix'!E5
C27: ='Unit Mix'!B6 | D27: ='Unit Mix'!C6 | E27: =+D27*F27 | F27: ='Unit Mix'!D6 | G27: =IF(ISERROR(F27/$F$28),"",(F27/$F$28)) | H27: =IF(ISERROR(I27/D27),"",(I27/D27)) | I27: ='Unit Mix'!E6
D28: ='Unit Mix'!C8 | E28: ='Unit Mix'!C7 | F28: =+SUM(F24:F27) | G28: =+SUM(G24:G27) | H28: ='Unit Mix'!F8 | I28: ='Unit Mix'!E8
L30: =K30/330
B32: BASE BUDGET
C34: USES | E34: COST | F34: PER UNIT | G34: PSF | K34: ORIGINATION/FINANCING FEE | N34: % | O34: COST
C35: =+'Soft Cost Detail'!B6 | E35: =+'Soft Cost Detail'!E6 | F35: =IF(ISERROR(E35/$F$28),"",(E35/$F$28)) | G35: =+F35/Total_Unit_wtavg_SF | K35: SR. ORIGINATION | M35: =E70 | O35: =+M35*N35
C36: =+'Soft Cost Detail'!B13 | E36: =+'Soft Cost Detail'!E13 | F36: =IF(ISERROR(E36/$F$28),"",(E36/$F$28)) | G36: =+F36/Total_Unit_wtavg_SF | K36: BROKER | M36: =M35 | O36: =+N36*M36
C37: =+'Soft Cost Detail'!B29 | E37: =+'Soft Cost Detail'!E29 | F37: =IF(ISERROR(E37/$F$28),"",(E37/$F$28)) | G37: =+F37/Total_Unit_wtavg_SF | K37: MEZZANINE APPLICATION | M37: =+E69 | O37: =+N37
C38: =+'Soft Cost Detail'!B37 | E38: =+'Soft Cost Detail'!E37 | F38: =IF(ISERROR(E38/$F$28),"",(E38/$F$28)) | G38: =+F38/Total_Unit_wtavg_SF | K38: MEZZANINE ORIGINATION | M38: =E69 | O38: =+N38*M38
C39: =+'Soft Cost Detail'!B46 | E39: =+'Soft Cost Detail'!E46 | F39: =IF(ISERROR(E39/$F$28),"",(E39/$F$28)) | G39: =+F39/Total_Unit_wtavg_SF | K39: BROKER | M39: =M38 | O39: =+N39*M39
C40: =+'Soft Cost Detail'!B52 | E40: =+'Soft Cost Detail'!E52 | F40: =IF(ISERROR(E40/$F$28),"",(E40/$F$28)) | G40: =+F40/Total_Unit_wtavg_SF | K40: EQUITY ORIGINATION | M40: =+E68*(1-M10) | O40: =+M40*N40
C41: =+'Soft Cost Detail'!B64 | E41: =+'Soft Cost Detail'!E64 | F41: =IF(ISERROR(E41/$F$28),"",(E41/$F$28)) | G41: =+F41/Total_Unit_wtavg_SF | K41: BROKER | M41: =+M40 | O41: =+N41*M41
C42: =+'Soft Cost Detail'!B83 | E42: =+'Soft Cost Detail'!E83 | F42: =IF(ISERROR(E42/$F$28),"",(E42/$F$28)) | G42: =+F42/Total_Unit_wtavg_SF | O42: =+SUM(O35:O41)
C43: =+'Soft Cost Detail'!B90 | E43: =+'Soft Cost Detail'!E90 | F43: =IF(ISERROR(E43/$F$28),"",(E43/$F$28)) | G43: =+F43/Total_Unit_wtavg_SF
C44: =+'Soft Cost Detail'!B115 | E44: =+'Soft Cost Detail'!E115 | F44: =IF(ISERROR(E44/$F$28),"",(E44/$F$28)) | G44: =+F44/Total_Unit_wtavg_SF
C45: =+'Soft Cost Detail'!B131 | E45: =+'Soft Cost Detail'!E131 | F45: =IF(ISERROR(E45/$F$28),"",(E45/$F$28)) | G45: =+F45/Total_Unit_wtavg_SF
C46: =+'Soft Cost Detail'!B134 | E46: =+'Soft Cost Detail'!E134 | F46: =IF(ISERROR(E46/$F$28),"",(E46/$F$28)) | G46: =+F46/Total_Unit_wtavg_SF
C47: =+'Soft Cost Detail'!B147 | E47: =+'Soft Cost Detail'!E147 | F47: =IF(ISERROR(E47/$F$28),"",(E47/$F$28)) | G47: =+F47/Total_Unit_wtavg_SF
C48: =+'Soft Cost Detail'!B150 | E48: =+'Soft Cost Detail'!E150 | F48: =IF(ISERROR(E48/$F$28),"",(E48/$F$28)) | G48: =+F48/Total_Unit_wtavg_SF
C49: =+'Soft Cost Detail'!B160 | E49: =+'Soft Cost Detail'!E160 | F49: =IF(ISERROR(E49/$F$28),"",(E49/$F$28)) | G49: =+F49/Total_Unit_wtavg_SF | I49: DEV. FEE | N49: `
...

Sheet Soft Cost Detail
A2: Apartment Soft Cost Detail | F2: <-- Type "Help" to reset circular references
C4: Description | D4: Amount | E4: Totals | F4: Comments
G5: =Summary!E60 | I5: Land Sale Comps | J5: Acres | K5: Units | L5: Sale Date | M5: Sale Price | N5: Price/Acre | O5: Price/Unit
B6: LAND | E6: =SUM(D7:D12) | N6: =IFERROR(M6/J6,0) | O6: =IFERROR(M6/K6,0)
C7: Land | N7: =IFERROR(M7/J7,0) | O7: =IFERROR(M7/K7,0)
C8: Escrow Deposit | N8: =IFERROR(M8/J8,0) | O8: =IFERROR(M8/K8,0)
C9: Extension Fees | N9: =IFERROR(M9/J9,0) | O9: =IFERROR(M9/K9,0)
C10: Commissions | N10: =IFERROR(M10/J10,0) | O10: =IFERROR(M10/K10,0)
C11: Land Loan Interest | N11: =IFERROR(M12/J12,0) | O11: =IFERROR(M11/K11,0)
C12: Other Unallocated
B13: ARCHITECT | E13: =SUM(D14:D28)
C14: Architect
C15: Land Planning
C16: Schematic Design
C17: Design Development
C18: Construction Drawings
C19: Construction Administration
C20: M/E/P
C21: Structural
C22: Additional Services
C23: Owner Revisions
C24: Reimbursable
C25: Site Visits
... C28: Other Unallocated
B29: ENVIRONMENTAL | E29: =SUM(D30:D35)
C30: Environmental Level I
C31: Environmental Level II
C32: Asbestos/Lead Testing
C33: Radon Testing/System Design
C34: Rodent Letter
C35: Other Unallocated
B37: SURVEY | E37: =SUM(D38:D45)
C38: Boundary Survey
C39: ALTA/Topo Survey
C40: Tree Survey
C41: Construction Staking
C42: Existing As-Builts
C43: Final As-Builts
C44: Reimbursables
C45: Other Unallocated
...

Sheet Unit Mix
B2: TYPE | C2: SIZE (SF) | D2: # UNITS | E2: RENT/MONTH | F2: $/SF/MO | G2: UNIT MIX | I2: GARAGE UNITS | J2: =SUMIF(#REF!,"g",#REF!)
B3: STUDIO | F3: =IF(ISERROR(E3/C3),"",E3/C3) | G3: =IF(ISERROR(D3/D$7),"",(D3/D$7)) | J3: =J2/D7
B4: 1BR / 1BA | F4: =IF(ISERROR(E4/C4),"",E4/C4) | G4: =IF(ISERROR(D4/D$7),"",(D4/D$7))
B5: 2BR / 2BA | F5: =IF(ISERROR(E5/C5),"",E5/C5) | G5: =IF(ISERROR(D5/D$7),"",(D5/D$7))
B6: 3BR / 2BA | F6: =IF(ISERROR(E6/C6),"",E6/C6) | G6: =IF(ISERROR(D6/D$7),"",(D6/D$7)) | M6: =Summary!M129
B7: TOTALS: | C7: =SUMPRODUCT(C3:C6,D3:D6) | D7: =SUM(D3:D6) | G7: =SUM(G3:G6)
B8: AVERAGES: | C8: =IF(ISERROR(SUMPRODUCT(C3:C6,D3:D6)/D7),"",(SUMPRODUCT(C3:C6,D3:D6)/D7)) | E8: =IF(ISERROR(SUMPRODUCT(E3:E6,D3:D6)/D7),"",SUMPRODUCT(E3:E6,D3:D6)/D7) | F8: =IF(ISERROR(E8/C8),"",(E8/C8))

Sheet Draw and Leaseup Schedule
B1: =+Summary!B1
C2: =+Summary!C2
C3: =+Summary!C3
B5: CASH FLOW STATEMENT
F6: =IF(SUM(F7:AN7)=1,"","CHECK")
C7: HARD COSTS FROM CONSTRUCTION SCHEDULE | F7: =HLOOKUP(F11,'Construction Schedule'!$D$14:$AJ$20,7) | G7: =HLOOKUP(G11,'Construction Schedule'!$D$14:$AJ$20,7) | H7: =HLOOKUP(H11,'Construction Schedule'!$D$14:$AJ$20,7) | I7: =HLOOKUP(I11,'Construction Schedule'!$D$14:$AJ$20,7) | J7: =HLOOKUP(J11,'Construction Schedule'!$D$14:$AJ$20,7) | K7: =HLOOKUP(K11,'Construction Schedule'!$D$14:$AJ$20,7) | L7: =HLOOKUP(L11,'Construction Schedule'!$D$14:$AJ$20,7) | M7: =HLOOKUP(M11,'Construction Schedule'!$D$14:$AJ$20,7) | ... AN7: =HLOOKUP(AN11,'Construction Schedule'!$D$14:$AJ$20,7)
C9: STABILIZATION SCHEDULE | E9: 0 | F9: =IF((E44/Total_Number_Units)>=Summary!$F$16,1,0) | G9: =IF((F44/Total_Number_Units)>=Summary!$F$16,1,0) | H9: =IF((G44/Total_Number_Units)>=Summary!$F$16,1,0) | I9: =IF((H44/Total_Number_Units)>=Summary!$F$16,1,0) | J9: =IF((I44/Total_Number_Units)>=Summary!$F$16,1,0) | K9: =IF((J44/Total_Number_Units)>=Summary!$F$16,1,0) | L9: =IF((K44/Total_Number_Units)>=Summary!$F$16,1,0) | M9: =IF((L44/Total_Number_Units)>=Summary!$F$16,1,0) | ... AN9: =IF((AM44/Total_Number_Units)>=Summary!$F$16,1,0)
C10: LEASE UP SCHEDULE | E10: =+E11-Summary!$D$14+1 | F10: =+F11-Summary!$D$14+1 | G10: =+G11-Summary!$D$14+1 | H10: =+H11-Summary!$D$14+1 | I10: =+I11-Summary!$D$14+1 | J10: =+J11-Summary!$D$14+1 | K10: =+K11-Summary!$D$14+1 | L10: =+L11-Summary!$D$14+1 | ... AN10: =+AN11-Summary!$D$14+1
C11: MONTH SCHEDULE | E11: 0 | F11: =IF(E11>0,E11+1,IF(MONTH(E13)=MONTH(Summary!$D$13),1,0)) | G11: =IF(F11>0,F11+1,IF(MONTH(F13)=MONTH(Summary!$D$13),1,0)) | H11: =IF(G11>0,G11+1,IF(MONTH(G13)=MONTH(Summary!$D$13),1,0)) | I11: =IF(H11>0,H11+1,IF(MONTH(H13)=MONTH(Summary!$D$13),1,0)) | J11: =IF(I11>0,I11+1,IF(MONTH(I13)=MONTH(Summary!$D$13),1,0)) | K11: =IF(J11>0,J11+1,IF(MONTH(J13)=MONTH(Summary!$D$13),1,0)) | L11: =IF(K11>0,K11+1,IF(MONTH(K13)=MONTH(Summary!$D$13),1,0)) | M11: =IF(L11>0,L11+1,IF(MONTH(L13)=MONTH(Summary!$D$13),1,0)) | ... AN11: =IF(AM11>0,AM11+1,IF(MONTH(AM13)=MONTH(Summary!$D$13),1,0))
C12: DAYS IN MONTH | E12: =DAY(DATE(YEAR(E13),MONTH(E13)+1,)) | F12: =DAY(DATE(YEAR(F13),MONTH(F13)+1,)) | G12: =DAY(DATE(YEAR(G13),MONTH(G13)+1,)) | H12: =DAY(DATE(YEAR(H13),MONTH(H13)+1,)) | I12: =DAY(DATE(YEAR(I13),MONTH(I13)+1,)) | J12: =DAY(DATE(YEAR(J13),MONTH(J13)+1,)) | K12: =DAY(DATE(YEAR(K13),MONTH(K13)+1,)) | L12: =DAY(DATE(YEAR(L13),MONTH(L13)+1,)) | ... AN12: =DAY(DATE(YEAR(AN13),MONTH(AN13)+1,))
C13: MONTH | E13: =Summary!D12 | F13: =DATE(YEAR(E13),MONTH(E13)+1,1) | G13: =DATE(YEAR(F13),MONTH(F13)+1,1) | H13: =DATE(YEAR(G13),MONTH(G13)+1,1) | I13: =DATE(YEAR(H13),MONTH(H13)+1,1) | J13: =DATE(YEAR(I13),MONTH(I13)+1,1) | K13: =DATE(YEAR(J13),MONTH(J13)+1,1) | L13: =DATE(YEAR(K13),MONTH(K13)+1,1) | M13: =DATE(YEAR(L13),MONTH(L13)+1,1) | ... AN13: =DATE(YEAR(AM13),MONTH(AM13)+1,1)
D14: BUDGET | AO14: Totals | AP14: Check
B15: =IF(ROUND(D15,4)=ROUND(AO15,4),"","X") | C15: =+Summary!C35 | D15: =+Land_Cost | E15: =$D15*E140 | F15: =$D15*F140 | G15: =$D15*G140 | H15: =$D15*H140 | I15: =$D15*I140 | J15: =$D15*J140 | K15: =$D15*K140 | L15: =$D15*L140 | ... AN15: =$D15*AN140 | AO15: =SUM(E15:AN15) | AP15: =IF(ROUND(AO15,3)=ROUND(D15,3),"ok", "no")
B16: =IF(ROUND(D16,4)=ROUND(AO16,4),"","X") | C16: =+Summary!C36 | D16: =+Architect | E16: =$D16*E141 | F16: =$D16*F141 | G16: =$D16*G141 | H16: =$D16*H141 | I16: =$D16*I141 | J16: =$D16*J141 | K16: =$D16*K141 | L16: =$D16*L141 | ... AN16: =$D16*AN141 | AO16: =SUM(E16:AN16) | AP16: =IF(ROUND(AO16,3)=ROUND(D16,3),"ok", "no")
B17: =IF(ROUND(D17,4)=ROUND(AO17,4),"","X") | C17: =+Summary!C37 | D17: =+Environmental_Costs | E17: =$D17*E142 | F17: =$D17*F142 | G17: =$D17*G142 | H17: =$D17*H142 | I17: =$D17*I142 | J17: =$D17*J142 | K17: =$D17*K142 | L17: =$D17*L142 | ... AN17: =$D17*AN142 | AO17: =SUM(E17:AN17) | AP17: =IF(ROUND(AO17,3)=ROUND(D17,3),"ok", "no")
B18: =IF(ROUND(D18,4)=ROUND(AO18,4),"","X") | C18: =+Summary!C38 | D18: =+Survey | E18: =$D18*E143 | F18: =$D18*F143 | G18: =$D18*G143 | H18: =$D18*H143 | I18: =$D18*I143 | J18: =$D18*J143 | K18: =$D18*K143 | L18: =$D18*L143 | ... AN18: =$D18*AN143 | AO18: =SUM(E18:AN18) | AP18: =IF(ROUND(AO18,3)=ROUND(D18,3),"ok", "no")
B19: =IF(ROUND(D19,4)=ROUND(AO19,4),"","X") | C19: =+Summary!C39 | D19: =+Soils_Testing | E19: =$D19*E144 | F19: =$D19*F144 | G19: =$D19*G144 | H19: =$D19*H144 | I19: =$D19*I144 | J19: =$D19*J144 | K19: =$D19*K144 | L19: =$D19*L144 | ... AN19: =$D19*AN144 | AO19: =SUM(E19:AN19) | AP19: =IF(ROUND(AO19,3)=ROUND(D19,3),"ok", "no")
B20: =IF(ROUND(D20,4)=ROUND(AO20,4),"","X") | C20: =+Summary!C40 | D20: =+Engineering | E20: =$D20*E145 | F20: =$D20*F145 | G20: =$D20*G145 | H20: =$D20*H145 | I20: =$D20*I145 | J20: =$D20*J145 | K20: =$D20*K145 | L20: =$D20*L145 | ... AN20: =$D20*AN145 | AO20: =SUM(E20:AN20) | AP20: =IF(ROUND(AO20,3)=ROUND(D20,3),"ok", "no")
B21: =IF(ROUND(D21,4)=ROUND(AO21,4),"","X") | C21: =+Summary!C41 | D21: =+Legal_Closing | E21: =$D21*E146 | F21: =$D21*F146 | G21: =$D21*G146 | H21: =$D21*H146 | I21: =$D21*I146 | J21: =$D21*J146 | K21: =$D21*K146 | L21: =$D21*L146 | ... AN21: =$D21*AN146 | AO21: =SUM(E21:AN21) | AP21: =IF(ROUND(AO21,3)=ROUND(D21,3),"ok", "no")
B22: =IF(ROUND(D22,4)=ROUND(AO22,4),"","X") | C22: =+Summary!C42 | D22: =+Taxes_Insurance | E22: =$D22*E147 | F22: =$D22*F147 | G22: =$D22*G147 | H22: =$D22*H147 | I22: =$D22*I147 | J22: =$D22*J147 | K22: =$D22*K147 | L22: =$D22*L147 | ... AN22: =$D22*AN147 | AO22: =SUM(E22:AN22) | AP22: =IF(ROUND(AO22,3)=ROUND(D22,3),"ok", "no")
B23: =IF(ROUND(D23,4)=ROUND(AO23,4),"","X") | C23: =+Summary!C43 | D23: =+Financing_Costs | E23: =$D23*E148 | F23: =$D23*F148 | G23: =$D23*G148 | H23: =$D23*H148 | I23: =$D23*I148 | J23: =$D23*J148 | K23: =$D23*K148 | L23: =$D23*L148 | ... AN23: =$D23*AN148 | AO23: =SUM(E23:AN23) | AP23: =IF(ROUND(AO23,3)=ROUND(D23,3),"ok", "no")
B24: =IF(ROUND(D24,4)=ROUND(AO24,4),"","X") | C24: =+Summary!C44 | D24: =+Muni_Fees | E24: =$D24*E149 | F24: =$D24*F149 | G24: =$D24*G149 | H24: =$D24*H149 | I24: =$D24*I149 | J24: =$D24*J149 | K24: =$D24*K149 | L24: =$D24*L149 | ... AN24: =$D24*AN149 | AO24: =SUM(E24:AN24) | AP24: =IF(ROUND(AO24,3)=ROUND(D24,3),"ok", "no")
B25: =IF(ROUND(D25,4)=ROUND(AO25,4),"","X") | C25: =+Summary!C45 | D25: =+Interest_Reserve | E25: =IF('Soft Cost Detail'!$E$2="help",0,+E117+('Soft Cost Detail'!$D$133*(E117)/($AO$117))) | F25: =IF('Soft Cost Detail'!$E$2="help",0,+F117+('Soft Cost Detail'!$D$133*(F117)/($AO$117))) | G25: =IF('Soft Cost Detail'!$E$2="help",0,+G117+('Soft Cost Detail'!$D$133*(G117)/($AO$117))) | H25: =IF('Soft Cost Detail'!$E$2="help",0,+H117+('Soft Cost Detail'!$D$133*(H117)/($AO$117))) | I25: =IF('Soft Cost Detail'!$E$2="help",0,+I117+('Soft Cost Detail'!$D$133*(I117)/($AO$117))) | J25: =IF('Soft Cost Detail'!$E$2="help",0,+J117+('Soft Cost Detail'!$D$133*(J117)/($AO$117))) | K25: =IF('Soft Cost Detail'!$E$2="help",0,+K117+('Soft Cost Detail'!$D$133*(K117)/($AO$117))) | L25: =IF('Soft Cost Detail'!$E$2="help",0,+L117+('Soft Cost Detail'!$D$133*(L117)/($AO$117))) | ... AN25: =IF('Soft Cost Detail'!$E$2="help",0,+AN117+('Soft Cost Detail'!$D$133*(AN117)/($AO$117))) | AO25: =SUM(E25:AN25) | AP25: =IF(ROUND(AO25,3)=ROUND(D25,3),"ok", "no")
B26: =IF(ROUND(D26,4)=ROUND(AO26,4),"","X") | C26: =+Summary!C46 | D26: =+Startup_Costs | E26: =$D26*E151 | F26: =$D26*F151 | G26: =$D26*G151 | H26: =$D26*H151 | I26: =$D26*I151 | J26: =$D26*J151 | K26: =$D26*K151 | L26: =$D26*L151 | ... AN26: =$D26*AN151 | AO26: =SUM(E26:AN26) | AP26: =IF(ROUND(AO26,3)=ROUND(D26,3),"ok", "no")
B27: =IF(ROUND(D27,4)=ROUND(AO27,4),"","X") | C27: =+Summary!C47 | D27: =+Summary!E47 | F27: =IF(F71<0,-F71,0) | G27: =IF(G71<0,-G71,0) | H27: =IF(H71<0,-H71,0) | I27: =IF(I71<0,-I71,0) | J27: =IF(J71<0,-J71,0) | K27: =IF(K71<0,-K71,0) | L27: =IF(L71<0,-L71,0) | M27: =IF(M71<0,-M71,0) | ... AN27: =IF(AN71<0,-AN71,0) | AO27: =SUM(E27:AN27) | AP27: =IF(ROUND(AO27,3)=ROUND(D27,3),"ok", "no")
B28: =IF(ROUND(D28,4)=ROUND(AO28,4),"","X") | C28: =+Summary!C48 | D28: =+FFE | E28: =$D28*E153 | F28: =$D28*F153 | G28: =$D28*G153 | H28: =$D28*H153 | I28: =$D28*I153 | J28: =$D28*J153 | K28: =$D28*K153 | L28: =$D28*L153 | ... AN28: =$D28*AN153 | AO28: =SUM(E28:AN28) | AP28: =IF(ROUND(AO28,3)=ROUND(D28,3),"ok", "no")
B29: =IF(ROUND(D29,4)=ROUND(AO29,4),"","X") | C29: =+Summary!C49 | D29: =+Development_Fees | E29: =$D29*E154 | F29: =$D29*F154 | G29: =$D29*G154 | H29: =$D29*H154 | I29: =$D29*I154 | J29: =$D29*J154 | K29: =$D29*K154 | L29: =$D29*L154 | ... AN29: =$D29*AN154 | AO29: =SUM(E29:AN29) | AP29: =IF(ROUND(AO29,3)=ROUND(D29,3),"ok", "no")
B30: =IF(ROUND(D30,4)=ROUND(AO30,4),"","X") | C30: =+Summary!C50 | D30: =+Gurantee_Fees | E30: =$D30*E155 | F30: =$D30*F155 | G30: =$D30*G155 | H30: =$D30*H155 | I30: =$D30*I155 | J30: =$D30*J155 | K30: =$D30*K155 | L30: =$D30*L155 | ... AN30: =$D30*AN155 | AO30: =SUM(E30:AN30) | AP30: =IF(ROUND(AO30,3)=ROUND(D30,3),"ok", "no")
B31: =IF(ROUND(D31,4)=ROUND(AO31,4),"","X") | C31: =+Summary!C51 | D31: =+Const_Mgmnt_Fees | E31: =$D31*E156 | F31: =$D31*F156 | G31: =$D31*G156 | H31: =$D31*H156 | I31: =$D31*I156 | J31: =$D31*J156 | K31: =$D31*K156 | L31: =$D31*L156 | ... AN31: =$D31*AN156 | AO31: =SUM(E31:AN31) | AP31: =IF(ROUND(AO31,3)=ROUND(D31,3),"ok", "no")
B32: =IF(ROUND(D32,4)=ROUND(AO32,4),"","X") | C32: =+Summary!C52 | D32: =+SoftCost_Conting | E32: 0 | F32: =SUM(F16:F31)*Summary!$H$52 | G32: =SUM(G16:G31)*Summary!$H$52 | H32: =SUM(H16:H31)*Summary!$H$52 | I32: =SUM(I16:I31)*Summary!$H$52 | J32: =SUM(J16:J31)*Summary!$H$52 | K32: =SUM(K16:K31)*Summary!$H$52 | L32: =SUM(L16:L31)*Summary!$H$52 | M32: =SUM(M16:M31)*Summary!$H$52 | ... AC32: =SUM(AC16:AC31)*Summary!$H$52 | AD32: =SUM(D32-SUM(F32:AC32)) | AE32: =SUM(AE16:AE31)*Summary!$H$52 | AF32: =SUM(AF16:AF31)*Summary!$H$52 | AG32: =SUM(AG16:AG31)*Summary!$H$52 | AH32: =SUM(AH16:AH31)*Summary!$H$52 | AI32: =SUM(AI16:AI31)*Summary!$H$52 | AJ32: =SUM(AJ16:AJ31)*Summary!$H$52 | AK32: =SUM(AK16:AK31)*Summary!$H$52 | AL32: =SUM(AL16:AL31)*Summary!$H$52 | ... AN32: =SUM(AN16:AN31)*Summary!$H$52 | AO32: =SUM(E32:AN32) | AP32: =IF(ROUND(AO32,3)=ROUND(D32,3),"ok", "no")
B33: =IF(ROUND(D33,4)=ROUND(AO33,4),"","X") | C33: =+Summary!C53 | D33: =+Hard_Costs | E33: =+$D$33*E7 | F33: =+$D$33*F7 | G33: =+$D$33*G7 | H33: =+$D$33*H7 | I33: =+$D$33*I7 | J33: =+$D$33*J7 | K33: =+$D$33*K7 | L33: =+$D$33*L7 | ... AN33: =+$D$33*AN7 | AO33: =SUM(E33:AN33) | AP33: =IF(ROUND(AO33,3)=ROUND(D33,3),"ok", "no")
B34: =IF(ROUND(D34,4)=ROUND(AO34,4),"","X") | C34: =+Summary!C54 | D34: =+HardCost_Conting | E34: =+E33*Summary!$H$54 | F34: 0 | G34: 0 | H34: 100000 | I34: 0 | J34: 125000 | K34: 0 | L34: 0 | M34: 150000 | N34: 0 | O34: 0 | P34: 150000 | Q34: 0 | R34: 150000 | S34: 0 | T34: 0 | U34: 125000 | V34: 0 | W34: 0 | X34: 125000 | Y34: 0 | Z34: 0 | AA34: =D34-SUM(E34:Z34) | AB34: =+AB33*Summary!$H$54 | AC34: =+AC33*Summary!$H$54 | AD34: =+AD33*Summary!$H$54 | AE34: =+AE33*Summary!$H$54 | AF34: =+AF33*Summary!$H$54 | AG34: =+AG33*Summary!$H$54 | AH34: =+AH33*Summary!$H$54 | AI34: =+AI33*Summary!$H$54 | ... AN34: =+AN33*Summary!$H$54 | AO34: =SUM(E34:AN34) | AP34: =IF(ROUND(AO34,3)=ROUND(D34,3),"ok", "no")
B35: =IF(ROUND(D35,4)=ROUND(AO35,4),"","X") | C35: =+Summary!C55 | D35: =+Summary!E55 | E35: =+D35 | AO35: =SUM(E35:AN35) | AP35: =IF(ROUND(AO35,3)=ROUND(D35,3),"ok", "no")
B36: =IF(ROUND(D36,4)=ROUND(AO36,4),"","X") | C36: =+Summary!C56 | D36: =+Summary!E56 | E36: =+D36 | AO36: =SUM(E36:AN36) | AP36: =IF(ROUND(AO36,3)=ROUND(D36,3),"ok", "no")
B37: =IF(ROUND(D37,4)=ROUND(AO37,4),"","X") | C37: =+Summary!C57 | D37: =+Summary!E57 | E37: =+D37 | AO37: =SUM(E37:AN37) | AP37: =IF(ROUND(AO37,3)=ROUND(D37,3),"ok", "no") | AQ37: W= winter mo.
B38: =IF(ROUND(D38,4)=ROUND(AO38,4),"","X") | C38: TOTAL | D38: =SUM(D15:D37) | E38: =SUM(E15:E37) | F38: =SUM(F15:F37) | G38: =SUM(G15:G37) | H38: =SUM(H15:H37) | I38: =SUM(I15:I37) | J38: =SUM(J15:J37) | K38: =SUM(K15:K37) | ... AN38: =SUM(AN15:AN37) | AO38: =SUM(E38:AN38) | AP38: =IF(ROUND(AO38,3)=ROUND(D38,3),"ok", "no") | AS38: Month | AT38: Leases
AQ39: W | AR39: 1 | AS39: January | AT39: =IF(AQ39="w",Summary!$F$14,Summary!$F$13)
C40: INCOME | AQ40: W | AR40: 2 | AS40: February | AT40: =IF(AQ40="w",Summary!$F$14,Summary!$F$13)
C41: UNITS DELIVERED PER MONTH | F41: =IF(E42>1,MIN(Summary!$F$12,Total_Number_Units-E42),IF(F$11>=Summary!$D$14,Summary!$F$12,0)) | G41: =IF(F42>1,MIN(Summary!$F$12,Total_Number_Units-F42),IF(G$11>=Summary!$D$14,Summary!$F$12,0)) | H41: =IF(G42>1,MIN(Summary!$F$12,Total_Number_Units-G42),IF(H$11>=Summary!$D$14,Summary!$F$12,0)) | I41: =IF(H42>1,MIN(Summary!$F$12,Total_Number_Units-H42),IF(I$11>=Summary!$D$14,Summary!$F$12,0)) | J41: =IF(I42>1,MIN(Summary!$F$12,Total_Number_Units-I42),IF(J$11>=Summary!$D$14,Summary!$F$12,0)) | K41: =IF(J42>1,MIN(Summary!$F$12,Total_Number_Units-J42),IF(K$11>=Summary!$D$14,Summary!$F$12,0)) | L41: =IF(K42>1,MIN(Summary!$F$12,Total_Number_Units-K42),IF(L$11>=Summary!$D$14,Summary!$F$12,0)) | M41: =IF(L42>1,MIN(Summary!$F$12,Total_Number_Units-L42),IF(M$11>=Summary!$D$14,Summary!$F$12,0)) | ... AN41: =IF(AM42>1,MIN(Summary!$F$12,Total_Number_Units-AM42),IF(AN$11>=Summary!$D$14,Summary!$F$12,0)) | AR41: 3 | AS41: March | AT41: =IF(AQ41="w",Summary!$F$14,Summary!$F$13)
C42: CUMULATIVE | G42: 0 | H42: 0 | I42: 0 | J42: 0 | K42: 0 | L42: 0 | M42: 0 | N42: 0 | O42: 0 | P42: 0 | Q42: =Q41 | R42: =SUM($F$41:R41) | S42: =SUM($F$41:S41) | T42: =SUM($F$41:T41) | U42: =SUM($F$41:U41) | V42: =SUM($F$41:V41) | W42: =SUM($F$41:W41) | X42: =SUM($F$41:X41) | Y42: =SUM($F$41:Y41) | ... AN42: =SUM($F$41:AN41) | AP42: Occup | AR42: 4 | AS42: April | AT42: =IF(AQ42="w",Summary!$F$14,Summary!$F$13)
...

Sheet Exit Summary Calculations
B1: =+Summary!B1
C2: =+Summary!C2
C3: =+Summary!C3
B6: EXIT SUMMARY CALCULATIONS
C9: STABILIZATION SCHEDULE | E9: =+'Draw and Leaseup Schedule'!E9 | F9: =+'Draw and Leaseup Schedule'!F9 | G9: =+'Draw and Leaseup Schedule'!G9 | H9: =+'Draw and Leaseup Schedule'!H9 | I9: =+'Draw and Leaseup Schedule'!I9 | J9: =+'Draw and Leaseup Schedule'!J9 | K9: =+'Draw and Leaseup Schedule'!K9 | L9: =+'Draw and Leaseup Schedule'!L9 | ... AN9: =+'Draw and Leaseup Schedule'!AN9
C10: LEASE UP SCHEDULE | E10: =+'Draw and Leaseup Schedule'!E10 | F10: =+'Draw and Leaseup Schedule'!F10 | G10: =+'Draw and Leaseup Schedule'!G10 | H10: =+'Draw and Leaseup Schedule'!H10 | I10: =+'Draw and Leaseup Schedule'!I10 | J10: =+'Draw and Leaseup Schedule'!J10 | K10: =+'Draw and Leaseup Schedule'!K10 | L10: =+'Draw and Leaseup Schedule'!L10 | ... AN10: =+'Draw and Leaseup Schedule'!AN10
C11: MONTH SCHEDULE | E11: =+'Draw and Leaseup Schedule'!E11 | F11: =+'Draw and Leaseup Schedule'!F11 | G11: =+'Draw and Leaseup Schedule'!G11 | H11: =+'Draw and Leaseup Schedule'!H11 | I11: =+'Draw and Leaseup Schedule'!I11 | J11: =+'Draw and Leaseup Schedule'!J11 | K11: =+'Draw and Leaseup Schedule'!K11 | L11: =+'Draw and Leaseup Schedule'!L11 | ... AN11: =+'Draw and Leaseup Schedule'!AN11
C12: DAYS IN MONTH | E12: =+'Draw and Leaseup Schedule'!E12 | F12: =+'Draw and Leaseup Schedule'!F12 | G12: =+'Draw and Leaseup Schedule'!G12 | H12: =+'Draw and Leaseup Schedule'!H12 | I12: =+'Draw and Leaseup Schedule'!I12 | J12: =+'Draw and Leaseup Schedule'!J12 | K12: =+'Draw and Leaseup Schedule'!K12 | L12: =+'Draw and Leaseup Schedule'!L12 | ... AN12: =+'Draw and Leaseup Schedule'!AN12
C13: MONTH | E13: =+'Draw and Leaseup Schedule'!E13 | F13: =+'Draw and Leaseup Schedule'!F13 | G13: =+'Draw and Leaseup Schedule'!G13 | H13: =+'Draw and Leaseup Schedule'!H13 | I13: =+'Draw and Leaseup Schedule'!I13 | J13: =+'Draw and Leaseup Schedule'!J13 | K13: =+'Draw and Leaseup Schedule'!K13 | L13: =+'Draw and Leaseup Schedule'!L13 | ... AN13: =+'Draw and Leaseup Schedule'!AN13
A15: PROJECT RETURNS SUMMARY
B16: UNTRENDED
C17: PROJECT EQUITY IN/OUT | E17: =-Summary!E68 | F17: ='Draw and Leaseup Schedule'!F86 | G17: ='Draw and Leaseup Schedule'!G86 | H17: ='Draw and Leaseup Schedule'!H86 | I17: ='Draw and Leaseup Schedule'!I86 | J17: ='Draw and Leaseup Schedule'!J86 | K17: ='Draw and Leaseup Schedule'!K86 | L17: ='Draw and Leaseup Schedule'!L86 | M17: ='Draw and Leaseup Schedule'!M86 | ... AN17: ='Draw and Leaseup Schedule'!AN86
C18: SALES PROCEEDS | AN18: =+'Exit Summary'!E32
C19: TOTALS | E19: =+E17+E18 | F19: =+F17+F18 | G19: =+G17+G18 | H19: =+H17+H18 | I19: =+I17+I18 | J19: =+J17+J18 | K19: =+K17+K18 | L19: =+L17+L18 | ... AN19: =+AN17+AN18 | AO19: =(1+IRR(E19:AN19,0.02))^12-1 | AP19: <= project IRR
B21: TRENDED - YEAR 3
C22: PROJECT EQUITY IN/OUT | E22: =-Summary!E68 | F22: ='Draw and Leaseup Schedule'!F86 | G22: ='Draw and Leaseup Schedule'!G86 | H22: ='Draw and Leaseup Schedule'!H86 | I22: ='Draw and Leaseup Schedule'!I86 | J22: ='Draw and Leaseup Schedule'!J86 | K22: ='Draw and Leaseup Schedule'!K86 | L22: ='Draw and Leaseup Schedule'!L86 | M22: ='Draw and Leaseup Schedule'!M86 | ... AN22: ='Draw and Leaseup Schedule'!AN86
C23: SALES PROCEEDS | AN23: =+'Exit Summary'!H32
C24: TOTALS | E24: =+E22+E23 | F24: =+F22+F23 | G24: =+G22+G23 | H24: =+H22+H23 | I24: =+I22+I23 | J24: =+J22+J23 | K24: =+K22+K23 | L24: =+L22+L23 | ... AN24: =+AN22+AN23 | AO24: =(1+IRR(E24:AN24,0.02))^12-1 | AP24: <= project IRR
B26: PREFERRED RETURN
C27: INVESTOR EQUITY IN/OUT | E27: =-Summary!E68 | F27: ='Draw and Leaseup Schedule'!F86 | G27: ='Draw and Leaseup Schedule'!G86 | H27: ='Draw and Leaseup Schedule'!H86 | I27: ='Draw and Leaseup Schedule'!I86 | J27: ='Draw and Leaseup Schedule'!J86 | K27: ='Draw and Leaseup Schedule'!K86 | L27: ='Draw and Leaseup Schedule'!L86 | M27: ='Draw and Leaseup Schedule'!M86 | ... AN27: ='Draw and Leaseup Schedule'!AN86
C28: SOLVER | AN28: =+'Exit Summary'!N39
C29: TOTALS | E29: =+E27+E28 | F29: =+F27+F28 | G29: =+G27+G28 | H29: =+H27+H28 | I29: =+I27+I28 | J29: =+J27+J28 | K29: =+K27+K28 | L29: =+L27+L28 | ... AN29: =+AN27+AN28 | AO29: =(1+IRR(E29:AN29,0.02))^12-1
C31: AVAILABLE AFTER PREF. | AN31: =AN18-AN28
A33: INVESTOR RETURNS SUMMARY
B35: UNTRENDED
C36: INVESTOR EQUITY | D36: =1-Summary!$M$10 | E36: =+'Draw and Leaseup Schedule'!$D$89*D36 | AO36: =+SUM(E36:AN36)
C37: Cash Flow | E37: =-E36 | F37: =+'Draw and Leaseup Schedule'!F$86*$D36 | G37: =+'Draw and Leaseup Schedule'!G$86*$D36 | H37: =+'Draw and Leaseup Schedule'!H$86*$D36 | I37: =+'Draw and Leaseup Schedule'!I$86*$D36 | J37: =+'Draw and Leaseup Schedule'!J$86*$D36 | K37: =+'Draw and Leaseup Schedule'!K$86*$D36 | L37: =+'Draw and Leaseup Schedule'!L$86*$D36 | M37: =+'Draw and Leaseup Schedule'!M$86*$D36 | ... AN37: =+'Draw and Leaseup Schedule'!AN$86*$D36 | AO37: =+SUM(E37:AN37)+AO36
C38: Return of Equity | AN38: =-AN54
C39: Pref from sale | AN39: =-AN57
C40: Sales profits | AN40: =-(AN60+AN63+AN66)
C41: IRR Calculation | E41: =SUM(E37:E40) | F41: =SUM(F37:F40) | G41: =SUM(G37:G40) | H41: =SUM(H37:H40) | I41: =SUM(I37:I40) | J41: =SUM(J37:J40) | K41: =SUM(K37:K40) | L41: =SUM(L37:L40) | ... AN41: =SUM(AN37:AN40) | AO41: =(1+IRR(E41:AN41,0.02))^12-1
B44: TRENDED
C45: INVESTOR EQUITY | D45: =1-Summary!$M$10 | E45: =+'Draw and Leaseup Schedule'!$D$89*D45
C46: Cash Flow | E46: =-E45 | F46: =+'Draw and Leaseup Schedule'!F$86*$D45 | G46: =+'Draw and Leaseup Schedule'!G$86*$D45 | H46: =+'Draw and Leaseup Schedule'!H$86*$D45 | I46: =+'Draw and Leaseup Schedule'!I$86*$D45 | J46: =+'Draw and Leaseup Schedule'!J$86*$D45 | K46: =+'Draw and Leaseup Schedule'!K$86*$D45 | L46: =+'Draw and Leaseup Schedule'!L$86*$D45 | M46: =+'Draw and Leaseup Schedule'!M$86*$D45 | ... AN46: =+'Draw and Leaseup Schedule'!AN$86*$D45
C47: Return of Equity | AN47: =-AP54
C48: Pref from sale | AN48: =-AP57
C49: Sales profits | AN49: =-AP60-AP63-AP66
C50: IRR Calculation | E50: =SUM(E46:E49) | F50: =SUM(F46:F49) | G50: =SUM(G46:G49) | H50: =SUM(H46:H49) | I50: =SUM(I46:I49) | J50: =SUM(J46:J49) | K50: =SUM(K46:K49) | L50: =SUM(L46:L49) | ... AN50: =SUM(AN46:AN49) | AO50: =(1+IRR(E50:AN50,0.02))^12-1
AN52: UNTRENDED | AP52: TRENDED
A53: Proceeds after Debt | AN53: =+AN18 | AP53: =+'Exit Summary'!H32
...

Sheet Exit Summary
B2: =Summary!B1 | M2: =Summary!B1
C5: CAPITALIZATION | M5: SENSITIVITY ANALYSIS
C6: CONSTRUCTION LOAN | E6: =Summary!E70 | F6: =+E6/Total_Number_Units | G6: =E6/$E$9
C7: MEZZ OR PREFERRED EQUITY | E7: =Summary!E69 | F7: =+E7/Total_Number_Units | G7: =E7/$E$9
C8: COMMON EQUITY | E8: =Summary!E68 | F8: =+E8/Total_Number_Units | G8: =E8/$E$9
E9: =SUM(E6:E8) | F9: =SUM(F6:F8) | G9: =E9/$E$9
M10: TOTAL PROCEEDS ABOVE COST
C13: Rent/SF | E13: =+Summary!D95
C14: Rental Income | E14: =+E13*'Unit Mix'!#REF!*12
C15: Other Income | E15: =SUM(Summary!G97:G102)
C16: Vacancy Loss | E16: =+Summary!G104+Summary!G105
C17: Expenses | E17: =-Summary!G123
C18: NOI | E18: =SUM(E14:E17)
C19: EXIT ASSUMPTIONS | E19: UNTRENDED | F19: PER UNIT | H19: TRENDED (YEAR 3) | I19: PER UNIT | N19: CAP RATE
C20: IN PLACE NOI (assumes no rent growth) | E20: =+E18 | F20: =+E20/Total_Number_Units | H20: =Summary!M178 | I20: =+H20/Total_Number_Units | M20: =E23 | O20: =+N20+0.0025 | P20: =+O20+0.0025 | Q20: =+P20+0.0025 | R20: =+Q20+0.0025 | S20: =+R20+0.0025 | T20: =+S20+0.0025
C21: EXIT CAP | E21: =+Summary!M12 | H21: =+E21 | L21: RENTS | M21: =+M22-0.1 | O21: #REF! | P21: #REF! | Q21: #REF! | R21: #REF! | S21: #REF! | T21: #REF!
C22: PLUS BUYER'S NPV FOR TAX ABATEMENTS | M22: =+M23-0.1 | N22: #REF! | O22: #REF! | P22: #REF! | Q22: #REF! | R22: #REF! | S22: #REF! | T22: #REF!
C23: GROSS SALE PRICE | E23: =E20/E21 | F23: =+E23/Total_Number_Units | H23: =H20/H21 | I23: =+H23/Total_Number_Units | M23: ='Unit Mix'!F8 | N23: #REF! | O23: #REF! | P23: #REF! | Q23: #REF! | R23: #REF! | S23: #REF! | T23: #REF!
C24: LESS DISPOSITION FEE | E24: =-E23*D24 | F24: =+E24/Total_Number_Units | H24: =-H23*D24 | I24: =+H24/Total_Number_Units | M24: =M23+0.1 | N24: #REF! | O24: #REF! | P24: #REF! | Q24: #REF! | R24: #REF! | S24: #REF! | T24: #REF!
C25: NET SALES PROCEEDS | E25: =E23+E24+E22 | F25: =+E25/Total_Number_Units | H25: =H23+H24 | I25: =+H25/Total_Number_Units | M25: =M24+0.1 | N25: #REF! | O25: #REF! | P25: #REF! | Q25: #REF! | R25: #REF! | S25: #REF! | T25: #REF!
C27: PROFIT AVAILABLE FOR DISTRIBUTION
C28: NET SALE PROCEEDS | E28: =E25 | H28: =H25
C29: LESS: END CONSTRUTION LOAN BALANCE: | E29: =-'Draw and Leaseup Schedule'!AN110 | H29: =-'Draw and Leaseup Schedule'!AN110 | M29: TP PROCEEDS
C30: LESS: ENDING MEZZ LOAN BALANCE: | E30: =-'Draw and Leaseup Schedule'!AN105 | H30: =-'Draw and Leaseup Schedule'!AN105 | N30: CAP RATE
C31: LESS: MEZZ EXIT FEE: | E31: =E30*D31 | H31: =H30*D31 | M31: =+E53 | O31: =+N31+0.0025 | P31: =+O31+0.0025 | Q31: =+P31+0.0025 | R31: =+Q31+0.0025 | S31: =+R31+0.0025 | T31: =+S31+0.0025
C32: SALES PROCEEDS AFTER DEBT | E32: =SUM(E28:E31) | H32: =SUM(H28:H31) | L32: RENTS | M32: =+M33-0.1 | O32: #REF! | P32: #REF! | Q32: #REF! | R32: #REF! | S32: #REF! | T32: #REF!
C33: LESS: REPAY EQUITY | E33: =-MIN($E$8,E32) | H33: =-MIN($E$8,H32) | M33: =+M34-0.1 | N33: #REF! | O33: #REF! | P33: #REF! | Q33: #REF! | R33: #REF! | S33: #REF! | T33: #REF!
C34: LESS: REMAINING PREF | D34: =+Summary!M11 | E34: =+'Exit Summary Calculations'!AN57+'Exit Summary Calculations'!AN58 | H34: =+'Exit Summary Calculations'!AP57+'Exit Summary Calculations'!AP58 | M34: ='Unit Mix'!F8 | N34: #REF! | O34: #REF! | P34: #REF! | Q34: #REF! | R34: #REF! | S34: #REF! | T34: #REF!
C35: AVAILABLE FOR DISTRIBUTION | E35: =SUM(E32:E34) | H35: =SUM(H32:H34) | M35: =M34+0.1 | N35: #REF! | O35: #REF! | P35: #REF! | Q35: #REF! | R35: #REF! | S35: #REF! | T35: #REF!
M36: =M35+0.1 | N36: #REF! | O36: #REF! | P36: #REF! | Q36: #REF! | R36: #REF! | S36: #REF! | T36: #REF!
C37: FIRST IRR HURRDLE | E37: IRR
C38: Investor Proceeds | D38: =90%*65% | E38: =-'Exit Summary Calculations'!AN60 | H38: =-'Exit Summary Calculations'!AP60
C39: Developer Proceeds | D39: =1-D38 | E39: =-'Exit Summary Calculations'!AN61 | H39: =-'Exit Summary Calculations'!AP61
C41: Residual | E41: =+E35-E38-E39 | H41: =+H35-H38-H39
C43: SECOND IRR HURRDLE | E43: IRR
C44: Investor Proceeds | D44: =90%*35% | E44: =-'Exit Summary Calculations'!AN63 | H44: =-'Exit Summary Calculations'!AP63
C45: Developer Proceeds | D45: =1-D44 | E45: =-'Exit Summary Calculations'!AN64 | H45: =-'Exit Summary Calculations'!AP64
C47: Residual | E47: =+E41-E44-E45 | H47: =+H41-H44-H45
C49: Investor Proceeds | E49: =-'Exit Summary Calculations'!AN66 | H49: =-'Exit Summary Calculations'!AP66
C50: Developer Proceeds | D50: =1-D49 | E50: =-'Exit Summary Calculations'!AN67 | H50: =-'Exit Summary Calculations'!AP67
...

Sheet Tables
A1: BASE BUDGET | S1: EXIT ASSUMPTIONS | U1: UNTRENDED | V1: TRENDED (YEAR 3) | X1: EXIT CAP SENSITIVITY
S2: IN PLACE NOI | U2: ='Exit Summary'!E20 | V2: ='Exit Summary'!H20 | X2: RATE | Z2: =Y2+0.0025 | AA2: =Z2+0.0025 | AB2: =AA2+0.0025 | AC2: =AB2+0.0025
B3: USES | C3: COST | D3: PER UNIT | E3: PSF | N3: OPERATING INCOME | O3: ANNUAL INCOME | P3: MONTHLY | Q3: ANNUAL/UNIT | S3: EXIT CAP | U3: ='Exit Summary'!E21 | V3: ='Exit Summary'!H21 | X3: SALE
B4: =Summary!C35 | C4: =Summary!E35 | D4: =Summary!F35 | E4: =Summary!G35 | N4: GROSS RENT INCOME | O4: =Summary!G95 | P4: =O4/12 | Q4: =O4/Total_Number_Units | S4: GROSS SALE PRICE | U4: ='Exit Summary'!E23 | V4: ='Exit Summary'!H23 | X4: PER/UNIT | Y4: =Y3/Total_Number_Units | Z4: =Z3/Total_Number_Units | AA4: =AA3/Total_Number_Units | AB4: =AB3/Total_Number_Units | AC4: =AC3/Total_Number_Units
B5: =Summary!C36 | C5: =Summary!E36 | D5: =Summary!F36 | E5: =Summary!G36 | N5: PLUS: MISC FEES | O5: =Summary!G100 | P5: =O5/12 | Q5: =O5/Total_Number_Units | S5: LESS DISPOSITION FEE | U5: ='Exit Summary'!E24 | V5: ='Exit Summary'!H24 | X5: PROMOTE | Y5: ='Exit Summary'!N34 | Z5: ='Exit Summary'!O34 | AA5: ='Exit Summary'!P34 | AB5: ='Exit Summary'!Q34 | AC5: ='Exit Summary'!R34
B6: =Summary!C37 | C6: =Summary!E37 | D6: =Summary!F37 | E6: =Summary!G37 | N6: PLUS: MANAGED WIFI | O6: =Summary!G99 | P6: =O6/12 | Q6: =O6/Total_Number_Units | S6: NET SALES PROCEEDS | U6: ='Exit Summary'!E25 | V6: ='Exit Summary'!H25
B7: =Summary!C38 | C7: =Summary!E38 | D7: =Summary!F38 | E7: =Summary!G38 | N7: PLUS: UTILITY REIUMBURSEMENT | O7: =Summary!G97 | P7: =O7/12 | Q7: =O7/Total_Number_Units
B8: =Summary!C39 | C8: =Summary!E39 | D8: =Summary!F39 | E8: =Summary!G39 | N8: GROSS POTENTIAL INCOME | O8: =SUM(O4:O7) | P8: =SUM(P4:P7) | Q8: =SUM(Q4:Q7)
B9: =Summary!C40 | C9: =Summary!E40 | D9: =Summary!F40 | E9: =Summary!G40 | N9: LESS: VACANCY | O9: =Summary!G104 | P9: =O9/12 | Q9: =O9/Total_Number_Units
B10: =Summary!C41 | C10: =Summary!E41 | D10: =Summary!F41 | E10: =Summary!G41 | N10: LESS: NON-REVENUE UNITS & BAD DEBT | O10: =Summary!G105 | P10: =O10/12 | Q10: =O10/Total_Number_Units
B11: =Summary!C42 | C11: =Summary!E42 | D11: =Summary!F42 | E11: =Summary!G42 | N11: EFFECTIVE GROSS INCOME | O11: =SUM(O8:O10) | P11: =SUM(P8:P10) | Q11: =SUM(Q8:Q10)
B12: =Summary!C43 | C12: =Summary!E43 | D12: =Summary!F43 | E12: =Summary!G43 | N12: OPERATING EXPENSES
B13: =Summary!C44 | C13: =Summary!E44 | D13: =Summary!F44 | E13: =Summary!G44 | N13: G&A | O13: =Summary!G111 | P13: =O13/12 | Q13: =O13/Total_Number_Units
B14: =Summary!C45 | C14: =Summary!E45 | D14: =Summary!F45 | E14: =Summary!G45 | N14: LEASING & MARKETING | O14: =Summary!G112 | P14: =O14/12 | Q14: =O14/Total_Number_Units
B15: =Summary!C46 | C15: =Summary!E46 | D15: =Summary!F46 | E15: =Summary!G46 | N15: PAYROLL & RELATED | O15: =Summary!G113 | P15: =O15/12 | Q15: =O15/Total_Number_Units
B16: =Summary!C47 | C16: =Summary!E47 | D16: =Summary!F47 | E16: =Summary!G47 | N16: UTILITIES (GROSS) | O16: =Summary!G114 | P16: =O16/12 | Q16: =O16/Total_Number_Units
B17: =Summary!C48 | C17: =Summary!E48 | D17: =Summary!F48 | E17: =Summary!G48 | N17: REDECORATING/MAKE READY | O17: =Summary!G115 | P17: =O17/12 | Q17: =O17/Total_Number_Units
B18: =Summary!C49 | C18: =Summary!E49 | D18: =Summary!F49 | E18: =Summary!G49 | N18: LANDSCAPING / CONTRACT SERVICES | O18: =Summary!G116 | P18: =O18/12 | Q18: =O18/Total_Number_Units
B19: =Summary!C50 | C19: =Summary!E50 | D19: =Summary!F50 | E19: =Summary!G50 | N19: REPAIRS & MAINTENANCE / CAM | O19: =Summary!G117 | P19: =O19/12 | Q19: =O19/Total_Number_Units
B20: =Summary!C51 | C20: =Summary!E51 | D20: =Summary!F51 | E20: =Summary!G51 | N20: TOTAL CONTROLLABLE | O20: =SUM(O13:O19) | P20: =SUM(P13:P19) | Q20: =SUM(Q13:Q19)
B21: =Summary!C52 | C21: =Summary!E52 | D21: =Summary!F52 | E21: =Summary!G52 | N21: INSURANCE | O21: =Summary!G119 | P21: =O21/12 | Q21: =O21/Total_Number_Units
B22: =Summary!C53 | C22: =Summary!E53 | D22: =Summary!F53 | E22: =Summary!G53 | N22: REAL ESTATE TAXES | O22: =Summary!G120 | P22: =O22/12 | Q22: =O22/Total_Number_Units
B23: =Summary!C54 | C23: =Summary!E54 | D23: =Summary!F54 | E23: =Summary!G54 | N23: MGMT FEE | O23: =Summary!G121 | P23: =O23/12 | Q23: =O23/Total_Number_Units
B24: =Summary!C58 | C24: =Summary!E58 | D24: =Summary!F58 | E24: =Summary!G58 | N24: CAPITAL RESERVES | O24: =Summary!G122 | P24: =O24/12 | Q24: =O24/Total_Number_Units
N25: TOTAL EXPENSES | O25: =SUM(O20:O24) | P25: =SUM(P20:P24) | Q25: =SUM(Q20:Q24)
A26: SOURCES & USES | N26: NET OPERATING INCOME | O26: =O11-O25 | P26: =P11-P25 | Q26: =Q11-Q25 | S26: PROFIT AVAILABLE FOR DISTRIBUTION
S27: NET SALE PROCEEDS | U27: ='Exit Summary'!E28 | V27: ='Exit Summary'!H28
B28: SOURCES | C28: AMOUNT | D28: % | F28: PER UNIT | G28: PSF | I28: SOURCES | J28: $ AMOUNT | K28: PER UNIT | L28: % | S28: LESS: END CONSTRUTION LOAN BALANCE: | U28: ='Exit Summary'!E29 | V28: ='Exit Summary'!H29
B29: EQUITY | C29: =Summary!E68 | D29: =Summary!F68 | F29: =Summary!G68 | G29: =Summary!H68 | I29: EQUITY | J29: =C29 | K29: =F29 | L29: =D29 | S29: LESS: ENDING MEZZ LOAN BALANCE: | U29: ='Exit Summary'!E30 | V29: ='Exit Summary'!H30
B30: MEZZANINE | C30: =Summary!E69 | D30: =Summary!F69 | F30: =Summary!G69 | G30: =Summary!H69 | I30: MEZZANINE | J30: =C30 | K30: =F30 | L30: =D30 | S30: LESS: MEZZ EXIT FEE: | U30: ='Exit Summary'!E31 | V30: ='Exit Summary'!H31
B31: SR. LOAN | C31: =Summary!E70 | D31: =Summary!F70 | F31: =Summary!G70 | G31: =Summary!H70 | I31: SR. LOAN | J31: =C31 | K31: =F31 | L31: =D31 | S31: SALES PROCEEDS AFTER DEBT | U31: ='Exit Summary'!E32 | V31: ='Exit Summary'!H32
B32: SUBTOTAL | C32: =SUM(C29:C31) | D32: 1 | F32: =SUM(F29:F31) | G32: =SUM(G29:G31) | I32: TOTAL | J32: =SUM(J29:J31) | K32: =SUM(K29:K31) | L32: =SUM(L29:L31) | S32: LESS: REPAY EQUITY | U32: ='Exit Summary'!E33 | V32: ='Exit Summary'!H33
B33: MEZZ INTEREST RESERVE (Current Pay) | C33: 0 | F33: 0 | G33: 0 | S33: LESS: REMAINING PREF | T33: ='Exit Summary'!D34 | U33: ='Exit Summary'!E34 | V33: ='Exit Summary'!H34
B34: TOTAL AFTER MEZZ INTEREST RESERVE | C34: =Summary!E73 | F34: =Summary!G73 | G34: =Summary!H73 | I34: USES | J34: COST | K34: PER UNIT | L34: % | S34: AVAILABLE FOR DISTRIBUTION | U34: ='Exit Summary'!E35 | V34: ='Exit Summary'!H35
I35: LAND | J35: =C37 | K35: =J35/Total_Number_Units | L35: =J35/$J$38
B36: USES | C36: COST | D36: % | F36: PER UNIT | G36: PSF | I36: HARD COSTS | J36: =C38 | K36: =J36/Total_Number_Units | L36: =J36/$J$38 | S36: FIRST IRR HURRDLE | T36: ='Exit Summary'!D37 | U36: ='Exit Summary'!E37
B37: LAND | C37: =Summary!E77 | D37: 0.094794356 | F37: =Summary!G77 | G37: =Summary!H77 | I37: SOFT COSTS | J37: =C39 | K37: =J37/Total_Number_Units | L37: =J37/$J$38 | S37: INVESTOR PROCEEDS | T37: ='Exit Summary'!D38 | U37: ='Exit Summary'!E38 | V37: ='Exit Summary'!H38
B38: HARD COSTS (INCL CONTINGENCY) | C38: =Summary!E78 | D38: 0.73854283 | F38: =Summary!G78 | G38: =Summary!H78 | I38: TOTAL | J38: =SUM(J35:J37) | K38: =SUM(K35:K37) | L38: =SUM(L35:L37) | S38: DEVELOPER PROCEEDS | T38: =1-T37 | U38: ='Exit Summary'!E39 | V38: ='Exit Summary'!H39
B39: SOFT COSTS | C39: =Summary!E79 | D39: 0.16666282 | F39: =Summary!G79 | G39: =Summary!H79
B40: SUBTOTAL | C40: =SUM(C37:C39) | D40: 1 | F40: =SUM(F37:F39) | G40: =SUM(G37:G39) | S40: RESIDUAL | U40: ='Exit Summary'!E41 | V40: ='Exit Summary'!H41
...

Sheet ABATEMENT SCHEDULE
D2: Valuation | E2: Assessed | F2: Millage Rate | G2: Mkt Rate RETs | H2: Abatement | I2: Taxes Paid | J2: Taxes Saved
B3: 2023 | D3: ='Soft Cost Detail'!D7 | E3: =+D3*0.4 | F3: =P11/P12 | G3: =F3*E3 | H3: 0 | I3: =G3 * (1 - H3) | J3: =G3-I3 | K3: Taxes during construction frozen; based on initial purchase price of raw land
B4: 2024 | D4: =D3 | E4: =+D4*0.4 | F4: =F3*(1+$E$23) | G4: =F4*E4 | H4: 0 | I4: =G4 | J4: =G4-I4 | K4: 100% Tax Abatement begins January of year following FULL project CO
B5: 2025 | C5: Year 1 | D5: =P9 | E5: =+D5*0.4 | F5: =F4*(1+$E$23) | G5: =F5*E5 | I5: =G5 * (1 - H5) | J5: =G5-I5
B6: 2026 | C6: Year 2 | D6: =D5*(1+$E$22) | E6: =+D6*0.4 | F6: =F5*(1+$E$23) | G6: =F6*E6 | I6: =G6 * (1 - H6) | J6: =G6-I6
B7: 2027 | C7: Year 3 | D7: =D6*(1+$E$22) | E7: =+D7*0.4 | F7: =F6*(1+$E$23) | G7: =F7*E7 | I7: =G7 * (1 - H7) | J7: =G7-I7 | L7: RET ESTIMATE FROM SANTI 3/17/22 | P7: based on actuals, the below are made up
B8: 2028 | C8: Year 4 | D8: =D7*(1+$E$22) | E8: =+D8*0.4 | F8: =F7*(1+$E$23) | G8: =F8*E8 | I8: =G8 * (1 - H8) | J8: =G8-I8 | M8: COUNTY RET | N8: CITY RET | O8: TOTALS | P8: assumptions to fit into abatement chart
B9: 2029 | C9: Year 5 | D9: =D8*(1+$E$22) | E9: =+D9*0.4 | F9: =F8*(1+$E$23) | G9: =F9*E9 | I9: =G9 * (1 - H9) | J9: =G9-I9 | L9: Hall Co Valuation | M9: =Summary!Q131*Total_Number_Units | N9: =M9 | P9: =N9
B10: 2030 | C10: Year 6 | D10: =D9*(1+$E$22) | E10: =+D10*0.4 | F10: =F9*(1+$E$23) | G10: =F10*E10 | I10: =G10 * (1 - H10) | J10: =G10-I10 | L10: Assessment Rate | P10: =M10
B11: 2031 | C11: Year 7 | D11: =D10*(1+$E$22) | E11: =+D11*0.4 | F11: =F10*(1+$E$23) | G11: =F11*E11 | I11: =G11 * (1 - H11) | J11: =G11-I11 | L11: Millage Rate | P11: =Summary!Q133
B12: 2032 | C12: Year 8 | D12: =D11*(1+$E$22) | E12: =+D12*0.4 | F12: =F11*(1+$E$23) | G12: =F12*E12 | I12: =G12 * (1 - H12) | J12: =G12-I12 | L12: Rate | M12: 1000 | N12: 1000 | P12: 1000
B13: 2033 | C13: Year 9 | D13: =D12*(1+$E$22) | E13: =+D13*0.4 | F13: =F12*(1+$E$23) | G13: =F13*E13 | I13: =G13 * (1 - H13) | J13: =G13-I13 | L13: RET - TOTAL | M13: =M9*M10*M11/M12 | N13: =N9*N10*N11/N12 | O13: =M13+N13 | P13: =O13
B14: 2034 | C14: Year 10 | D14: =D13*(1+$E$22) | E14: =+D14*0.4 | F14: =F13*(1+$E$23) | G14: =F14*E14 | I14: =G14 * (1 - H14) | J14: =G14-I14 | L14: RET - PER UNIT | M14: =M13/Total_Number_Units | N14: =N13/Total_Number_Units | O14: =M14+N14 | P14: =O14
B15: 2035 | C15: Year 11 | D15: =D14*(1+$E$22) | E15: =+D15*0.4 | F15: =F14*(1+$E$23) | G15: =F15*E15 | I15: =G15 * (1 - H15) | J15: =G15-I15
B16: 2036 | C16: Year 12 | D16: =D15*(1+$E$22) | E16: =+D16*0.4 | F16: =F15*(1+$E$23) | G16: =F16*E16 | I16: =G16 * (1 - H16) | J16: =G16-I16
B17: 2037 | C17: Year 13 | D17: =D16*(1+$E$22) | E17: =+D17*0.4 | F17: =F16*(1+$E$23) | G17: =F17*E17 | I17: =G17 * (1 - H17) | J17: =G17-I17
B18: 2038 | C18: Year 14 | D18: =D17*(1+$E$22) | E18: =+D18*0.4 | F18: =F17*(1+$E$23) | G18: =F18*E18 | I18: =G18 * (1 - H18) | J18: =G18-I18
B19: 2039 | C19: Year 15 | D19: =D18*(1+$E$22) | E19: =+D19*0.4 | F19: =F18*(1+$E$23) | G19: =F19*E19 | I19: =G19 * (1 - H19) | J19: =G19-I19
G20: =SUM(G3:G19) | I20: =SUM(I3:I19) | J20: =SUM(J3:J19)
C22: PROPERTY VALUE INCREASE / YR | H22: ABATEMENT VALUATION
C23: ANNUAL INCREASE IN VALUE | H23: DISCOUNT RATE
H24: PROJECT NOMINAL TAX SAVINGS | J24: =SUM(J3:J19)
H25: PROJECT NPV OF TAX SAVINGS | J25: =NPV($J$23,$J$3:$J$19)
H26: BUYER'S NOMINAL TAX SAVINGS | J26: =SUM(J5:J19)
H27: BUYER'S NPV OF TAX SAVINGS | J27: =NPV($J$23,$J$5:$J$19)

Sheet Forward Curves-Monthly
A1: Chatham Financial
A2: Weekly Forward Curves
A3: 46031
A6: Date | B6: 46035 | C6: 46066 | D6: 46094 | E6: 46125 | F6: 46155 | G6: 46188 | H6: 46216 | I6: 46247 | J6: 46279 | K6: 46308 | L6: 46339 | M6: 46370 | N6: 46400 | O6: 46434 | P6: 46461 | Q6: 46490 | R6: 46520 | S6: 46552 | T6: 46581 | U6: 46612 | V6: 46643 | W6: 46673 | X6: 46706 | Y6: 46734 | Z6: 46765 | AA6: 46797 | AB6: 46825 | AC6: 46856 | AD6: 46888 | AE6: 46917 | AF6: 46947 | AG6: 46979 | AH6: 47009 | AI6: 47039 | AJ6: 47070 | AK6: 47100 | AL6: 47134 | AM6: 47162 | AN6: 47190 | AO6: 47221 | AP6: 47252 | AQ6: 47282 | AR6: 47312 | AS6: 47343 | AT6: 47374 | AU6: 47406 | AV6: 47435 | AW6: 47465 | AX6: 47497 | AY6: 47527 | AZ6: 47555 | BA6: 47588 | BB6: 47616 | BC6: 47647 | BD6: 47679 | BE6: 47708 | BF6: 47739 | BG6: 47771 | BH6: 47800 | BI6: 47830 | BJ6: 47861 | BK6: 47892 | BL6: 47920 | BM6: 47952 | BN6: 47981 | BO6: 48012 | BP6: 48043 | BQ6: 48073 | BR6: 48106 | BS6: 48135 | BT6: 48165 | BU6: 48197 | BV6: 48226 | BW6: 48257 | BX6: 48288 | BY6: 48317 | BZ6: 48347 | CA6: 48379 | CB6: 48408 | CC6: 48439 | CD6: 48470 | CE6: 48500 | CF6: 48533 | CG6: 48561 | CH6: 48592 | CI6: 48624 | CJ6: 48652 | CK6: 48682 | CL6: 48712 | CM6: 48743 | CN6: 48773 | CO6: 48806 | CP6: 48835 | CQ6: 48865 | CR6: 48897 | CS6: 48926 | CT6: 48957 | CU6: 48988 | CV6: 49016 | CW6: 49047 | CX6: 49079 | CY6: 49108 | CZ6: 49138 | DA6: 49170 | DB6: 49200 | DC6: 49230 | DD6: 49261 | DE6: 49291 | DF6: 49325 | DG6: 49353 | DH6: 49381 | DI6: 49412 | DJ6: 49443 | DK6: 49473 | DL6: 49503 | DM6: 49534 | DN6: 49565 | DO6: 49597 | DP6: 49626 | DQ6: 49656 | DR6: 49688 | DS6: =EOMONTH(DR6,1) | DT6: =EOMONTH(DS6,1) | DU6: =EOMONTH(DT6,1) | DV6: =EOMONTH(DU6,1) | DW6: =EOMONTH(DV6,1) | DX6: =EOMONTH(DW6,1) | DY6: =EOMONTH(DX6,1) | DZ6: =EOMONTH(DY6,1) | ... FO6: =EOMONTH(FN6,1)
A8: 1 Month USD SOFR Forward Curve | B8: 0.0367532 | C8: 0.0366817 | D8: 0.0362892 | E8: 0.0358654 | F8: 0.0354297 | G8: 0.0343825 | H8: 0.033776 | I8: 0.0337776 | J8: 0.0323953 | K8: 0.0322982 | L8: 0.0322982 | M8: 0.0316857 | N8: 0.0316477 | O8: 0.0316393 | P8: 0.0316798 | Q8: 0.0316809 | R8: 0.0316837 | S8: 0.031838 | T8: 0.0319526 | U8: 0.032075 | V8: 0.0322057 | W8: 0.032359 | X8: 0.0325159 | Y8: 0.0326741 | Z8: 0.0328578 | AA8: 0.0330275 | AB8: 0.0331919 | AC8: 0.0333638 | AD8: 0.0335275 | AE8: 0.0336712 | AF8: 0.0338276 | AG8: 0.0339767 | AH8: 0.0341117 | AI8: 0.0342498 | AJ8: 0.0343799 | AK8: 0.0345197 | AL8: 0.0346453 | AM8: 0.0347455 | AN8: 0.034867 | AO8: 0.0349886 | AP8: 0.0351094 | AQ8: 0.0352219 | AR8: 0.035341 | AS8: 0.0354595 | AT8: 0.0355809 | AU8: 0.0356979 | AV8: 0.0358029 | AW8: 0.0359219 | AX8: 0.0360373 | AY8: 0.0361404 | AZ8: 0.0362691 | BA8: 0.0363907 | BB8: 0.0365107 | BC8: 0.0366468 | BD8: 0.0367828 | BE8: 0.036913 | BF8: 0.03706 | BG8: 0.0372068 | BH8: 0.0373426 | BI8: 0.0374954 | BJ8: 0.0376512 | BK8: 0.0377923 | BL8: 0.0379476 | BM8: 0.0380936 | BN8: 0.0382361 | BO8: 0.0383814 | BP8: 0.0385244 | BQ8: 0.0386691 | BR8: 0.0388034 | BS8: 0.0389348 | BT8: 0.0390683 | BU8: 0.0391996 | BV8: 0.0393202 | BW8: 0.0394469 | BX8: 0.0395712 | BY8: 0.0396812 | BZ8: 0.0398053 | CA8: 0.0399183 | CB8: 0.04003 | CC8: 0.0401428 | CD8: 0.0402492 | CE8: 0.0403657 | CF8: 0.0404663 | CG8: 0.0405636 | CH8: 0.040669 | CI8: 0.0407576 | CJ8: 0.0408606 | CK8: 0.0409543 | CL8: 0.0410558 | CM8: 0.0411525 | CN8: 0.0412619 | CO8: 0.041361 | CP8: 0.041451 | CQ8: 0.0415562 | CR8: 0.0416518 | CS8: 0.0417496 | CT8: 0.0418498 | CU8: 0.0419378 | CV8: 0.0420404 | CW8: 0.0421444 | CX8: 0.0422435 | CY8: 0.0423328 | CZ8: 0.0424376 | DA8: 0.0425364 | DB8: 0.0426286 | DC8: 0.0427291 | DD8: 0.0428244 | DE8: 0.0429372 | DF8: 0.0430337 | DG8: 0.0431108 | DH8: 0.0432129 | DI8: 0.043312 | DJ8: 0.043411 | DK8: 0.0435026 | DL8: 0.0436025 | DM8: 0.0437013 | DN8: 0.0438043 | DO8: 0.0439018 | DP8: 0.0439898 | DQ8: 0.0440937 | DR8: 0.0441907 | DS8: 0.031111148 | DT8: 0.031163302 | DU8: 0.03121115 | DV8: 0.031264201 | DW8: 0.031305965 | DX8: 0.031351077 | DY8: 0.031395549 | DZ8: 0.031426159 | EA8: 0.031465011 | EB8: 0.031498892 | EC8: 0.031529401 | ED8: 0.031554364 | EE8: 0.031581402 | EF8: 0.031601244 | EG8: 0.031618567 | EH8: 0.031633991 | EI8: 0.031642575 | EJ8: 0.031651805 | EK8: 0.031654685 | EL8: 0.031650168 | EM8: 0.031650304 | EN8: 0.031640136 | EO8: 0.031629919 | EP8: 0.031611305 | EQ8: 0.031594854 | ER8: 0.031576959 | ES8: 0.031554404 | ET8: 0.031535503 | EU8: 0.031512811 | EV8: 0.031487897 | EW8: 0.031466269 | EX8: 0.031435725 | EY8: 0.031412051 | EZ8: 0.031385309 | FA8: 0.031358244 | FB8: 0.03132408 | FC8: 0.03129427 | FD8: 0.031261176 | FE8: 0.031222336 | FF8: 0.031189361 | FG8: 0.031147179 | FH8: 0.031105815 | FI8: 0.031068874 | FJ8: 0.03102066 | FK8: 0.030978823 | FL8: 0.03093357 | FM8: 0.030881133 | FN8: 0.030832224 | FO8: 0.030782419
B33: Projected LIBOR Curve
B63: Projected Treasury Curve
A98: Notes
A99: (1) LIBOR and UST data courtesy of Bloomberg

Sheet Construction Schedule
A1: 46001
C2: Lengths | D2: Products
D3: Garden
D4: High Den Surface Park
D5: High Density Wrap
D6: Highrise
E14: =+D14+1 | F14: =+E14+1 | G14: =+F14+1 | H14: =+G14+1 | I14: =+H14+1 | J14: =+I14+1 | K14: =+J14+1 | L14: =+K14+1 | ... AJ14: =+AI14+1
C15: =+C25 | E15: =+E26 | F15: =+F26 | G15: =+G26 | H15: =+H26 | I15: =+I26 | J15: =+J26 | K15: =+K26 | L15: =+L26 | ... AJ15: =+AJ26
C16: =+C39 | E16: =+E40 | F16: =+F40 | G16: =+G40 | H16: =+H40 | I16: =+I40 | J16: =+J40 | K16: =+K40 | L16: =+L40 | ... AJ16: =+AJ40
C17: =+C55 | E17: =+E56 | F17: =+F56 | G17: =+G56 | H17: =+H56 | I17: =+I56 | J17: =+J56 | K17: =+K56 | L17: =+L56 | ... AJ17: =+AJ56
C18: =+C73 | E18: =+E74 | F18: =+F74 | G18: =+G74 | H18: =+H74 | I18: =+I74 | J18: =+J74 | K18: =+K74 | L18: =+L74 | ... AJ18: =+AJ74
C20: High Den Surface Park | E20: =VLOOKUP($C20,$C15:$AJ18,E14+2) | F20: =VLOOKUP($C20,$C15:$AJ18,F14+2) | G20: =VLOOKUP($C20,$C15:$AJ18,G14+2) | H20: =VLOOKUP($C20,$C15:$AJ18,H14+2) | I20: =VLOOKUP($C20,$C15:$AJ18,I14+2) | J20: =VLOOKUP($C20,$C15:$AJ18,J14+2) | K20: =VLOOKUP($C20,$C15:$AJ18,K14+2) | L20: =VLOOKUP($C20,$C15:$AJ18,L14+2) | ... AJ20: =VLOOKUP($C20,$C15:$AJ18,AJ14+2)
C25: =+D3
A26: =IF(SUM(E26:AJ26)=1,"","CHECK") | B26: =SUM(E26:AJ26) | C26: 22 | E26: =VLOOKUP($C26,$C27:$AJ36,E25+2,) | F26: =VLOOKUP($C26,$C27:$AJ36,F25+2,) | G26: =VLOOKUP($C26,$C27:$AJ36,G25+2,) | H26: =VLOOKUP($C26,$C27:$AJ36,H25+2,) | I26: =VLOOKUP($C26,$C27:$AJ36,I25+2,) | J26: =VLOOKUP($C26,$C27:$AJ36,J25+2,) | K26: =VLOOKUP($C26,$C27:$AJ36,K25+2,) | L26: =VLOOKUP($C26,$C27:$AJ36,L25+2,) | ... AJ26: =VLOOKUP($C26,$C27:$AJ36,AJ25+2,)
A27: =IF(SUM(E27:AJ27)=1,"","CHECK") | B27: =SUM(E27:AJ27)
A28: =IF(SUM(E28:AJ28)=1,"","CHECK") | B28: =SUM(E28:AJ28)
A29: =IF(SUM(E29:AJ29)=1,"","CHECK") | B29: =SUM(E29:AJ29)
A30: =IF(SUM(E30:AJ30)=1,"","CHECK") | B30: =SUM(E30:AJ30)
A31: =IF(SUM(E31:AJ31)=1,"","CHECK") | B31: =SUM(E31:AJ31)
A32: =IF(SUM(E32:AJ32)=1,"","CHECK") | B32: =SUM(E32:AJ32)
A33: =IF(SUM(E33:AJ33)=1,"","CHECK") | B33: =SUM(E33:AJ33)
A34: =IF(SUM(E34:AJ34)=1,"","CHECK") | B34: =SUM(E34:AJ34)
A35: =IF(SUM(E35:AJ35)=1,"","CHECK") | B35: =SUM(E35:AJ35)
A36: =IF(SUM(E36:AJ36)=1,"","CHECK") | B36: =SUM(E36:AJ36)
C39: =+D4
A40: =IF(SUM(E40:AJ40)=1,"","CHECK") | B40: =SUM(E40:AJ40) | C40: 22 | E40: =VLOOKUP($C40,$C41:$AJ50,E39+2,) | F40: =VLOOKUP($C40,$C41:$AJ50,F39+2,) | G40: =VLOOKUP($C40,$C41:$AJ50,G39+2,) | H40: =VLOOKUP($C40,$C41:$AJ50,H39+2,) | I40: =VLOOKUP($C40,$C41:$AJ50,I39+2,) | J40: =VLOOKUP($C40,$C41:$AJ50,J39+2,) | K40: =VLOOKUP($C40,$C41:$AJ50,K39+2,) | L40: =VLOOKUP($C40,$C41:$AJ50,L39+2,) | ... AJ40: =VLOOKUP($C40,$C41:$AJ50,AJ39+2,)
A41: =IF(SUM(E41:AJ41)=1,"","CHECK") | B41: =SUM(E41:AJ41)
A42: =IF(SUM(E42:AJ42)=1,"","CHECK") | B42: =SUM(E42:AJ42)
A43: =IF(SUM(E43:AJ43)=1,"","CHECK") | B43: =SUM(E43:AJ43)
A44: =IF(SUM(E44:AJ44)=1,"","CHECK") | B44: =SUM(E44:AJ44)
A45: =IF(SUM(E45:AJ45)=1,"","CHECK") | B45: =SUM(E45:AJ45)
A46: =IF(SUM(E46:AJ46)=1,"","CHECK") | B46: =SUM(E46:AJ46)
A47: =IF(SUM(E47:AJ47)=1,"","CHECK") | B47: =SUM(E47:AJ47)
A48: =IF(SUM(E48:AJ48)=1,"","CHECK") | B48: =SUM(E48:AJ48)
A49: =IF(SUM(E49:AJ49)=1,"","CHECK") | B49: =SUM(E49:AJ49)
A50: =IF(SUM(E50:AJ50)=1,"","CHECK") | B50: =SUM(E50:AJ50)
B51: =SUM(E51:AJ51)
B52: =SUM(E52:AJ52)
C55: =+D5
A56: =IF(SUM(E56:AJ56)=1,"","CHECK") | B56: =SUM(E56:AJ56) | C56: 22 | E56: =VLOOKUP($C56,$C57:$AJ66,E55+2,) | F56: =VLOOKUP($C56,$C57:$AJ66,F55+2,) | G56: =VLOOKUP($C56,$C57:$AJ66,G55+2,) | H56: =VLOOKUP($C56,$C57:$AJ66,H55+2,) | I56: =VLOOKUP($C56,$C57:$AJ66,I55+2,) | J56: =VLOOKUP($C56,$C57:$AJ66,J55+2,) | K56: =VLOOKUP($C56,$C57:$AJ66,K55+2,) | L56: =VLOOKUP($C56,$C57:$AJ66,L55+2,) | ... AJ56: =VLOOKUP($C56,$C57:$AJ66,AJ55+2,)
...
