Workbook
Name Building_Sale: #REF!
Name Building_Sale_Proceeds: #REF!
Name Circ_Breaker: #REF!
Name Circularity: #REF!
Name Company_Name: #REF!
Name Constr_End: #REF!
Name Constr_Months: #REF!
Name Constr_Start: #REF!
Name Fees_Mezzanine: #REF!
Name Fees_TL_A: #REF!
Name Fees_TL_B: #REF!
Name FFE_Costs: #REF!
Name FFE_Months: #REF!
Name FFE_Start: #REF!
Name Garage_Gross_SF: #REF!
Name Hard_Costs: #REF!
Name Interest_Mezzanine: #REF!
Name Interest_TL_A: #REF!
Name Interest_TL_B: #REF!
Name Land_Acquisition: #REF!
Name Land_Deposit: #REF!
Name Lot_SF: #REF!
Name Max_Dev_Equity: #REF!
Name Max_Investor_Equity: #REF!
Name Max_Mezzanine: #REF!
Name Max_TL_A: #REF!
Name Max_TL_B: #REF!
Name Monthly_Parking_Expenses: #REF!
Name Monthly_Parking_Revenue: #REF!
Name Months: #REF!
Name Office_Cap_Rate: #REF!
Name Office_Gross_SF: #REF!
Name Office_OpEx: #REF!
Name Office_Property_Tax: #REF!
Name Office_Rent: #REF!
Name Office_Rentable_SF: #REF!
Name Office_Selling_Fees: #REF!
Name Office_Tenant_End: #REF!
Name Office_Tenant_Fill_Months: #REF!
Name Office_Tenant_Start: #REF!
Name Office_TI_Cost: #REF!
Name Office_TI_End: #REF!
Name Office_TI_Months: #REF!
Name Office_TI_Start: #REF!
Name Office_Vacancy: #REF!
Name PerUnit: #REF!
Name Res_VacancyLoss1: '[1]Residential Assumptions'!$B$79
Name Soft_Costs: #REF!
Name Start_Date: #REF!
Name Status_Construction: #REF!
Name Status_Post_Construction: #REF!
Name Status_Pre_Construction: #REF!
Name Tier_1_Limit: #REF!
Name Tier_2_Limit: #REF!
Name Tier_3_Limit: #REF!
Name Total_Dev_Costs: #REF!
Name Units: #REF!
Name UnitsorRSF: #REF!

Sheet Project Assumptions
A1: =A5
A2: Project Assumptions
A3: Blue cells = your inputs (change these) Black cells = formulas (do not touch) Green cells = links from other tabs
A4: Project Name | H4: Base Development Fee Assumptions
A5: [Enter Property Name] | H5: Percentage Fee
H6: Calculate Fee on (type "X" to include):
A7: Project Size | H7: Land or Building Purchase
A8: Land Area (acres) | H8: Land Development and Site Work | K8: X
A9: Gross Square Feet | E9: 92000 | H9: Building Shell | K9: X
A10: NRSF Factor | E10: =89750/E9 | H10: Tenant Improvements: | I10: Hard Costs | K10: X
A11: Net Rentable Square Feet | E11: =E9*E10 | H11: Arch. & Eng. and Other Consultants | K11: X
H12: Legal, Marketing, Insurance, Taxes
A13: Project Dates | H13: Permits, Testing/Insp., Fees, Bonds | K13: X
A14: Land Acquisition Date | E14: End Date | H14: Leasing Commissions
A15: Period from Land Hold to Construction Start | E15: =MAX(EOMONTH(D14,D15-1),D14) | H15: Finance Fees
A16: Construction Period | E16: =EOMONTH(D14,D15+D16-1) | H16: Interest Expense / Loss to Breakeven
H17: Contingency
H18: Furniture and Equipment | K18: X
A19: Capitalization Assumptions | H19: Result
C20: Portion of | D20: Interest | E20: Funding | H20: Project Costs used for Calculation | K20: =IF($K$7="X",SUM('Detailed Project Costs'!$F$80),0)+IF($K$8="X",SUM('Detailed Project Costs'!$F$83),0)+IF($K$9="X",SUM('Detailed Project Costs'!$F$84),0)+IF($K$10="X",SUM('Detailed Project Costs'!$F$25),0)+IF($K$12="X",SUM('Detailed Project Costs'!$F$92),0)+IF($K$13="X",SUM('Detailed Project Costs'!$F$93),0)+IF($K$14="X",SUM('Detailed Project Costs'!$F$94),0)+IF($K$15="X",SUM('Detailed Project Costs'!$F$99),0)+IF($K$16="X",SUM('Detailed Project Costs'!$F$100),0)+IF($K$17="X",SUM('Detailed Project Costs'!$F$103),0)+IF($K$18="X",SUM('Detailed Project Costs'!$F$86),0)+IF($K$11="X",SUM('Detailed Project Costs'!$F$91),0)
C21: Project Costs | D21: Rate | E21: Order | H21: Base Development Fee | K21: =K20*K5
A22: Land Hold Period Capitalization:
A23: Bank Debt | C23: =C26 | D23: =D26 | E23: 2
A24: Equity | C24: =1-C23 | D24: N/A | E24: 1
A25: Construction Period Capitalization:
A26: Bank Debt | E26: 2
A27: Equity | C27: =1-C26 | D27: N/A | E27: 1
A30: Funding Amounts
C31: Land Hold | D31: Construction
C32: Period | D32: Period
A33: Bank Debt | C33: ='Project Returns'!E7 | D33: ='Project Returns'!F7
A34: Equity | C34: ='Project Returns'!E8 | D34: ='Project Returns'!F8
A35: Total | C35: ='Project Returns'!E9 | D35: ='Project Returns'!F9

Sheet Economic Assumptions
A1: ='Project Assumptions'!A1:J1
A2: Economic Assumptions
A5: Lease Assumptions
B6: Month | C6: Square | D6: Rental Rate | G6: Free Rent | I6: Leasing Commissions | K6: Tenant Improvements
B7: Commence | C7: Feet | D7: ($/sf) | I7: ($ amount) | K7: ($/sf)
B8: Beginning | D8: Net | E8: Expense | F8: Gross | G8: months | H8: Oper. Exp. | I8: Third Party | J8: In-House | K8: Hard | L8: Soft | M8: Lease
B9: w/ Month 1 * | D9: Rent | E9: Stop | F9: Rent | G9: up front | H9: Paid by | I9: Broker | J9: Broker | K9: Costs | L9: Costs | M9: Commence
A10: Office Lease #1 | F10: =D10+E10 | H10: Tenant | I10: ='Lease 1'!H22 | J10: ='Lease 1'!I22 | M10: =IF(B10>1, EDATE('Project Assumptions'!$E$16,'Economic Assumptions'!B10), " ")
F11: =D11+E11 | H11: Tenant | I11: ='Lease 2'!H22 | J11: ='Lease 3'!I22 | M11: =IF(B11>1, EDATE('Project Assumptions'!$E$16,'Economic Assumptions'!B11), " ")
F12: =D12+E12 | H12: Tenant | I12: ='Lease 3'!H22 | J12: ='Lease 3'!I22 | M12: =IF(B12>1, EDATE('Project Assumptions'!$E$16,'Economic Assumptions'!B12), " ")
F13: =D13+E13 | H13: Tenant | I13: ='Lease 4'!H22 | J13: ='Lease 4'!I22 | M13: =IF(B13>1, EDATE('Project Assumptions'!$E$16,'Economic Assumptions'!B13), " ")
F14: =D14+E14 | H14: Tenant | I14: ='Lease 5'!H22 | J14: ='Lease 5'!I22 | M14: =IF(B14>1, EDATE('Project Assumptions'!$E$16,'Economic Assumptions'!B14), " ")
F15: =D15+E15 | H15: Tenant | I15: ='Lease 6'!H22 | J15: ='Lease 6'!I22 | M15: =IF(B15>1, EDATE('Project Assumptions'!$E$16,'Economic Assumptions'!B15), " ")
F16: =D16+E16 | H16: Tenant | I16: ='Lease 7'!H22 | J16: ='Lease 7'!I22 | M16: =IF(B16>1, EDATE('Project Assumptions'!$E$16,'Economic Assumptions'!B16), " ")
F17: =D17+E17 | H17: Tenant | I17: ='Lease 8'!H22 | J17: ='Lease 9'!I22 | M17: =IF(B17>1, EDATE('Project Assumptions'!$E$16,'Economic Assumptions'!B17), " ")
F18: =D18+E18 | H18: Tenant | I18: ='Lease 9'!H22 | J18: ='Lease 9'!I22 | M18: =IF(B18>1, EDATE('Project Assumptions'!$E$16,'Economic Assumptions'!B18), " ")
F19: =D19+E19 | H19: Tenant | I19: ='Lease 10'!H22 | J19: ='Lease 10'!I22 | M19: =IF(B19>1, EDATE('Project Assumptions'!$E$16,'Economic Assumptions'!B19), " ")
F20: =D20+E20 | H20: Tenant | I20: ='Lease 11'!H22 | J20: ='Lease 11'!I22 | M20: =IF(B20>1, EDATE('Project Assumptions'!$E$16,'Economic Assumptions'!B20), " ")
A22: Total | C22: =SUM(C10:C21) | I22: =SUM(I10:I21) | J22: =SUM(J10:J21) | K22: =SUMPRODUCT(C10:C20,K10:K20) | L22: =SUMPRODUCT(C10:C20,L10:L20)
A25: Dates for Lease-Up and Stabilization | I25: Parking Spaces
A26: Lease-Up Date - | B26: full lease-up | E26: ='Project Assumptions'!D15+'Project Assumptions'!D16+MAX(MAX(B10:B19)-1,0) | G26: =EOMONTH('Project Assumptions'!$D$14,E26-1) | L26: # of Spaces
A27: Stabilization Date - | B27: full lease-up and end of free rent | E27: ='Project Assumptions'!D15+'Project Assumptions'!D16+MAX(MAX(B10+G10,B11+G11,B12+G12,B13+G13,B14+G14,B15+G15,B16+G16,B17+G17,B18+G18,B19+G19)-1,0) | G27: =EOMONTH('Project Assumptions'!$D$14,E27-1) | I27: Surface Lot(s)
I28: Garage - Free-Standing:
I29: Above Grade
A30: Operating Expense Assumptions | I30: Below Grade
A31: Operating Expenses on Vacant Space during Lease-Up (/s.f.) | I31: Total Parking Spaces | L31: =L27+L29+L30
A32: Operating Expenses on Leased Space during Free Rent (/s.f.) | I32: Total Parking Spaces per 1,000 Commercial NRSF | L32: =L31/('Project Assumptions'!E11/1000)
I33: GARAGE - Cost per Parking Space | L33: =('Detailed Project Costs'!F23+'Detailed Project Costs'!F24)/'Economic Assumptions'!L31
A35: Other Income Assumptions
A36: Other Income - annual amount at full lease-up (e.g. Parking) | E36: Parking Income
A39: Vacancy and Structural Reserve Assumtpions
B40: Vacancy | D40: Structural Reserve | G40: Gross Rental Income -
B41: Factor | D41: Factor | G41: Forward 12 Months
D42: % | E42: or /sf | G42: at Stabilization | H42: at Sale
A43: =A10 | G43: =C10*F10 | H43: =C10*F10
A44: =A11 | G44: =C11*F11 | H44: =C11*F11
A45: =A12 | G45: =C12*F12 | H45: =C12*F12
A46: =A13 | G46: =C13*F13 | H46: =C13*F13
A47: =A14 | G47: =C14*F14 | H47: =C14*F14
A48: =A15 | G48: =C15*F15 | H48: =C15*F15
...

Sheet Detailed Project Costs
A1: ='Project Assumptions'!A5
A2: Detailed Project Costs
A4: Gross Square Feet: | C4: ='Project Assumptions'!E9
A5: Net Rentable Square Feet: | C5: ='Project Assumptions'!E11
A7: Cost Category | D7: Input | F7: Budget
D8: Format | E8: Input | F8: Amount | G8: Notes
A9: Land Purchase | B9: Land Purchase | C9: Purchase Price | D9: $ | F9: =IF(D9="$",E9,IF(D9="NRSF",E9*$C$5,E9*$C$4))
C10: Other Land Purchase Costs | D10: $ | F10: =IF(D10="$",E10,IF(D10="NRSF",E10*$C$5,E10*$C$4))
C11: Due Diligence Costs | D11: $ | F11: =IF(D11="$",E11,IF(D11="NRSF",E11*$C$5,E11*$C$4))
B12: Land Closing | C12: Other Land Closing Costs | D12: $ | F12: =IF(D12="$",E12,IF(D12="NRSF",E12*$C$5,E12*$C$4))
A13: Land Development and Site Work | B13: Site Work | C13: Site Construction Contract | D13: GSF | F13: =IF(D13="$",E13,IF(D13="NRSF",E13*$C$5,E13*$C$4))
C14: Clearing and Grading | D14: $ | F14: =IF(D14="$",E14,IF(D14="NRSF",E14*$C$5,E14*$C$4))
C15: Other Site Work Costs | D15: $ | F15: =IF(D15="$",E15,IF(D15="NRSF",E15*$C$5,E15*$C$4))
B16: Off-Site | C16: Off-Site Roads | D16: $ | F16: =IF(D16="$",E16,IF(D16="NRSF",E16*$C$5,E16*$C$4))
C17: Other Off-Site | D17: $ | F17: =IF(D17="$",E17,IF(D17="NRSF",E17*$C$5,E17*$C$4))
B18: Landscaping and Irrigation | C18: Landscaping Construction Contract | D18: NRSF | F18: =IF(D18="$",E18,IF(D18="NRSF",E18*$C$5,E18*$C$4))
C19: Other Landscaping Costs | D19: NRSF | F19: =IF(D19="$",E19,IF(D19="NRSF",E19*$C$5,E19*$C$4))
A20: Building Shell | B20: Building Shell | C20: Shell Construction Contract | D20: GSF | F20: =IF(D20="$",E20,IF(D20="NRSF",E20*$C$5,E20*$C$4))
C21: Other Shell Costs | D21: $ | F21: =IF(D21="$",E21,IF(D21="NRSF",E21*$C$5,E21*$C$4))
C22: Multi-Tenant Corridors | D22: GSF | F22: =IF(D22="$",E22,IF(D22="NRSF",E22*$C$5,E22*$C$4))
B23: Structured Parking | C23: Structured Parking Cstr. Contract | D23: $ | F23: =IF(D23="$",E23,IF(D23="NRSF",E23*$C$5,E23*$C$4))
C24: Other Structured Parking Costs | D24: $ | F24: =IF(D24="$",E24,IF(D24="NRSF",E24*$C$5,E24*$C$4))
A25: Tenant Improvements (Hard & Soft) | B25: General TI Budget | C25: Hard Costs | D25: calculated | E25: N/A | F25: ='Economic Assumptions'!$K$22
C26: Soft Costs | D26: calculated | E26: N/A | F26: ='Economic Assumptions'!L22
A27: Arch. & Eng. and Other Consultants | B27: Architect (Shell) | C27: Contract (Architect) | D27: GSF | F27: =IF(D27="$",E27,IF(D27="NRSF",E27*$C$5,E27*$C$4))
C28: Reimbursables (Architect) | D28: GSF | F28: =IF(D28="$",E28,IF(D28="NRSF",E28*$C$5,E28*$C$4))
B29: Structural Eng. (Shell) | C29: Contract (Structural Engineer) | D29: GSF | F29: =IF(D29="$",E29,IF(D29="NRSF",E29*$C$5,E29*$C$4))
C30: Reimbursables (Structural Engineer) | D30: GSF | F30: =IF(D30="$",E30,IF(D30="NRSF",E30*$C$5,E30*$C$4))
B31: MEP Engineer | C31: Contract (MEP Engineer) | D31: GSF | F31: =IF(D31="$",E31,IF(D31="NRSF",E31*$C$5,E31*$C$4))
C32: Reimbursables (MEP Engineer) | D32: GSF | F32: =IF(D32="$",E32,IF(D32="NRSF",E32*$C$5,E32*$C$4))
B33: Landscape Architect | C33: Contract (Survey.) | D33: GSF | F33: =IF(D33="$",E33,IF(D33="NRSF",E33*$C$5,E33*$C$4))
C34: Reimbursables (Survey.) | D34: GSF | F34: =IF(D34="$",E34,IF(D34="NRSF",E34*$C$5,E34*$C$4))
B35: Specialty Consultants | C35: Specialty Consultants | D35: GSF | F35: =IF(D35="$",E35,IF(D35="NRSF",E35*$C$5,E35*$C$4))
C36: Specialty Consultants | D36: GSF | F36: =IF(D36="$",E36,IF(D36="NRSF",E36*$C$5,E36*$C$4))
A37: Legal, Marketing, Insurance & Taxes | B37: Legal | C37: Financing | D37: $ | F37: =IF(D37="$",E37,IF(D37="NRSF",E37*$C$5,E37*$C$4))
C38: Construction Contract Negotiation | D38: $ | F38: =IF(D38="$",E38,IF(D38="NRSF",E38*$C$5,E38*$C$4))
C39: Lease | D39: $ | F39: =IF(D39="$",E39,IF(D39="NRSF",E39*$C$5,E39*$C$4))
C40: Other Legal | D40: $ | F40: =IF(D40="$",E40,IF(D40="NRSF",E40*$C$5,E40*$C$4))
B41: Marketing | C41: Space Planning (prospects) | D41: NRSF | F41: =IF(D41="$",E41,IF(D41="NRSF",E41*$C$5,E41*$C$4))
C42: Marketing and Leasing Program | D42: $ | F42: =IF(D42="$",E42,IF(D42="NRSF",E42*$C$5,E42*$C$4))
...

Sheet Project Returns
A1: ='Project Assumptions'!A1:J1
A2: Project Returns
C4: Funding Amounts
E5: Land Hold | F5: Construction
E6: Period | F6: Period
C7: Bank Debt | E7: ='Detailed Cashflows'!D169 | F7: ='Detailed Cashflows'!D173
C8: Equity | E8: ='Detailed Cashflows'!D170 | F8: ='Detailed Cashflows'!D174
C9: Total | E9: =E7+E8 | F9: =F7+F8
A12: Yield at Stabilization
G13: at Stabilization | H13: at Sale
A14: Net Operating Income
A15: Rental Income (gross, or net for net lease structures) | F15: =G15/'Project Assumptions'!$E$11 | G15: =SUMPRODUCT('Economic Assumptions'!C10:C20,'Economic Assumptions'!F10:F20)*(1+0.037) | H15: =G15
A16: Parking Income | F16: =G16/'Project Assumptions'!$E$11 | G16: 0 | H16: ='Economic Assumptions'!H54
A17: Vacancy | F17: =G17/SUM($G$15:$G$16) | G17: =-SUMPRODUCT('Economic Assumptions'!G43:G52,'Economic Assumptions'!B43:B52) | H17: =-SUMPRODUCT('Economic Assumptions'!H43:H52,'Economic Assumptions'!B43:B52)
A18: Structural Reserve | F18: =G18/SUM($G$15:$G$16) | G18: =-SUMPRODUCT('Economic Assumptions'!G43:G52,'Economic Assumptions'!D43:D52)-SUMPRODUCT('Economic Assumptions'!C10:C19,'Economic Assumptions'!E43:E52) | H18: =-SUMPRODUCT('Economic Assumptions'!H43:H52,'Economic Assumptions'!D43:D52)-SUMPRODUCT('Economic Assumptions'!C10:C19,'Economic Assumptions'!E43:E52)
A19: Operating Expenses on Leased Space | F19: =G19/'Project Assumptions'!$E$11 | G19: =-SUMPRODUCT('Economic Assumptions'!C10:C19,'Economic Assumptions'!E10:E19,1-'Economic Assumptions'!B43:B52) | H19: =G19
A20: Net Operating Income | F20: =G20/'Project Assumptions'!$E$11 | G20: =SUM(G15:G19) | H20: =SUM(H15:H19)
A22: Total Project Costs
A23: Total Project Costs | F23: =G23/'Project Assumptions'!$E$11 | G23: ='Detailed Project Costs'!F74
A24: Project Cash Flow thru Stabilization | F24: =G24/'Project Assumptions'!$E$11 | G24: =-'Detailed Cashflows'!D243
A25: Equity Preferred Return, thru Stabilization | F25: =G25/'Project Assumptions'!$E$11 | G25: ='Detailed Cashflows'!D244
A26: Total Project Costs - w/ adjustments | F26: =G26/'Project Assumptions'!$E$11 | G26: =SUM(G23:G25)
A29: Sales Proceeds
A31: Stabilization Date | F31: ='Economic Assumptions'!E27 | G31: =EOMONTH('Project Assumptions'!D14,F31-1)
A32: Sale Date | F32: =IF(ISERROR(F31+(YEAR(G32)-YEAR(G31))*12+MONTH(G32)-MONTH(G31)),0,F31+(YEAR(G32)-YEAR(G31))*12+MONTH(G32)-MONTH(G31)) | G32: =G31+1 | H32: (Must be Stabilization Date or after)
A34: Commerical Sale Price
A35: Net Operating Income at Sale | G35: =H20
A36: Exit Capitalization Rate
A37: Gross Sale Price | F37: =G37/'Project Assumptions'!E9 | G37: =G35/G36
A39: Gross Sales Proceeds - based on NOI | F39: =G39/'Project Assumptions'!$E$11 | G39: =G37
A40: Transfer Taxes | G40: =$G$39*-F40
A41: Third Party Commission | G41: =$G$39*-F41
A42: In-House Commission | G42: =$G$39*-F42
A43: Legal / Miscellaneous Closing Costs | G43: =-F43
A44: Net Sales Proceeds | F44: =G44/'Project Assumptions'!E11 | G44: =G39+SUM(G40:G43)
A45: Project Cash Flow thru Sale * | G45: ='Detailed Cashflows'!D153-'Detailed Cashflows'!D154
A46: Total Distributions Available | G46: =G44+G45
A49: Distributions
A51: Debt Repayment | C51: Construction Period - Bank Debt | E51: ='Project Assumptions'!C26 | G51: =MIN((G23)*E51,$G$44+G45-'Detailed Cashflows'!D220+'Detailed Cashflows'!$D$221)
A53: Equity Preferred Return | C53: Rate - Land Hold Period
...

Sheet Detailed Cashflows
A1: ='Project Assumptions'!A5
A2: Detailed Cashflows
F4: Closing | G4: ='Project Assumptions'!D14 | H4: =EDATE(G4,1) | I4: =EDATE(H4,1) | J4: =EDATE(I4,1) | K4: =EDATE(J4,1) | L4: =EDATE(K4,1) | M4: =EDATE(L4,1) | N4: =EDATE(M4,1) | O4: =EDATE(N4,1) | ... DB4: =EDATE(DA4,1)
D5: Total | F5: 0 | G5: 1 | H5: 2 | I5: 3 | J5: 4 | K5: 5 | L5: 6 | M5: 7 | N5: 8 | O5: 9 | P5: 10 | Q5: 11 | R5: 12 | S5: 13 | T5: 14 | U5: 15 | V5: 16 | W5: 17 | X5: 18 | Y5: 19 | Z5: 20 | AA5: 21 | AB5: 22 | AC5: 23 | AD5: 24 | AE5: 25 | AF5: 26 | AG5: 27 | AH5: 28 | AI5: 29 | AJ5: 30 | AK5: 31 | AL5: 32 | AM5: 33 | AN5: 34 | AO5: 35 | AP5: 36 | AQ5: 37 | AR5: 38 | AS5: 39 | AT5: 40 | AU5: 41 | AV5: 42 | AW5: 43 | AX5: 44 | AY5: 45 | AZ5: 46 | BA5: 47 | BB5: 48 | BC5: 49 | BD5: 50 | BE5: 51 | BF5: 52 | BG5: 53 | BH5: 54 | BI5: 55 | BJ5: 56 | BK5: 57 | BL5: 58 | BM5: 59 | BN5: 60 | BO5: 61 | BP5: 62 | BQ5: 63 | BR5: 64 | BS5: 65 | BT5: 66 | BU5: 67 | BV5: 68 | BW5: 69 | BX5: 70 | BY5: 71 | BZ5: 72 | CA5: 73 | CB5: 74 | CC5: 75 | CD5: 76 | CE5: 77 | CF5: 78 | CG5: 79 | CH5: 80 | CI5: 81 | CJ5: 82 | CK5: 83 | CL5: 84 | CM5: 85 | CN5: 86 | CO5: 87 | CP5: 88 | CQ5: 89 | CR5: 90 | CS5: 91 | CT5: 92 | CU5: 93 | CV5: 94 | CW5: 95 | CX5: 96 | CY5: 97 | CZ5: 98 | DA5: 99 | DB5: 100 | DD5: Total
A6: Project Summary Costs
A8: Land or Building Purchase | D8: =DD8 | F8: =SUM(F29) | G8: =SUM(G29) | H8: =SUM(H29) | I8: =SUM(I29) | J8: =SUM(J29) | K8: =SUM(K29) | L8: =SUM(L29) | M8: =SUM(M29) | ... DB8: =SUM(DB29) | DD8: =SUM(F8:DB8)
A9: Land Development and Site Work | D9: =DD9 | F9: =SUM(F30:F32) | G9: =SUM(G30:G32) | H9: =SUM(H30:H32) | I9: =SUM(I30:I32) | J9: =SUM(J30:J32) | K9: =SUM(K30:K32) | L9: =SUM(L30:L32) | M9: =SUM(M30:M32) | ... DB9: =SUM(DB30:DB32) | DD9: =SUM(F9:DB9)
A10: Building Shell | D10: =DD10 | F10: =SUM(F33:F34) | G10: =SUM(G33:G34) | H10: =SUM(H33:H34) | I10: =SUM(I33:I34) | J10: =SUM(J33:J34) | K10: =SUM(K33:K34) | L10: =SUM(L33:L34) | M10: =SUM(M33:M34) | ... DB10: =SUM(DB33:DB34) | DD10: =SUM(F10:DB10)
A11: Tenant Improvements (Hard & Soft) | D11: =DD11 | F11: =SUM(F35,F46) | G11: =SUM(G35,G46) | H11: =SUM(H35,H46) | I11: =SUM(I35,I46) | J11: =SUM(J35,J46) | K11: =SUM(K35,K46) | L11: =SUM(L35,L46) | M11: =SUM(M35,M46) | ... DB11: =SUM(DB35,DB46) | DD11: =SUM(F11:DB11)
A12: Arch. & Eng. and Other Consultants | D12: =DD12 | F12: =SUM(F57:F61) | G12: =SUM(G57:G61) | H12: =SUM(H57:H61) | I12: =SUM(I57:I61) | J12: =SUM(J57:J61) | K12: =SUM(K57:K61) | L12: =SUM(L57:L61) | M12: =SUM(M57:M61) | ... DB12: =SUM(DB57:DB61) | DD12: =SUM(F12:DB12)
A13: Legal, Marketing, Insurance, Taxes | D13: =DD13 | F13: =SUM(F62:F70) | G13: =SUM(G62:G70) | H13: =SUM(H62:H70) | I13: =SUM(I62:I70) | J13: =SUM(J62:J70) | K13: =SUM(K62:K70) | L13: =SUM(L62:L70) | M13: =SUM(M62:M70) | ... DB13: =SUM(DB62:DB70) | DD13: =SUM(F13:DB13)
A14: Permits, Testing/Insp., Fees, Bonds | D14: =DD14 | F14: =SUM(F71:F74) | G14: =SUM(G71:G74) | H14: =SUM(H71:H74) | I14: =SUM(I71:I74) | J14: =SUM(J71:J74) | K14: =SUM(K71:K74) | L14: =SUM(L71:L74) | M14: =SUM(M71:M74) | ... DB14: =SUM(DB71:DB74) | DD14: =SUM(F14:DB14)
A15: Leasing Commissions | D15: =DD15 | F15: =SUM(F75,F87) | G15: =SUM(G75,G87) | H15: =SUM(H75,H87) | I15: =SUM(I75,I87) | J15: =SUM(J75,J87) | K15: =SUM(K75,K87) | L15: =SUM(L75,L87) | M15: =SUM(M75,M87) | ... DB15: =SUM(DB75,DB87) | DD15: =SUM(F15:DB15)
A16: Development Fee | D16: =DD16 | F16: =SUM(F99) | G16: =SUM(G99) | H16: =SUM(H99) | I16: =SUM(I99) | J16: =SUM(J99) | K16: =SUM(K99) | L16: =SUM(L99) | M16: =SUM(M99) | ... DB16: =SUM(DB99) | DD16: =SUM(F16:DB16)
A17: Finance Fees | D17: =DD17 | F17: =SUM(F100:F102) | G17: =SUM(G100:G102) | H17: =SUM(H100:H102) | I17: =SUM(I100:I102) | J17: =SUM(J100:J102) | K17: =SUM(K100:K102) | L17: =SUM(L100:L102) | M17: =SUM(M100:M102) | ... DB17: =SUM(DB100:DB102) | DD17: =SUM(F17:DB17)
A18: Interest / Loss to Breakeven | D18: =DD18 | F18: =F109+F110+F154 | G18: =G109+G110+G154 | H18: =H109+H110+H154 | I18: =I109+I110+I154 | J18: =J109+J110+J154 | K18: =K109+K110+K154 | L18: =L109+L110+L154 | M18: =M109+M110+M154 | ... DB18: =DB109+DB110+DB154 | DD18: =SUM(F18:DB18)
A19: Contingency | D19: =DD19 | F19: =SUM(F103:F104) | G19: =SUM(G103:G104) | H19: =SUM(H103:H104) | I19: =SUM(I103:I104) | J19: =SUM(J103:J104) | K19: =SUM(K103:K104) | L19: =SUM(L103:L104) | M19: =SUM(M103:M104) | ... DB19: =SUM(DB103:DB104) | DD19: =SUM(F19:DB19)
A20: Furniture and Equipment | D20: =DD20 | F20: =SUM(F105) | G20: =SUM(G105) | H20: =SUM(H105) | I20: =SUM(I105) | J20: =SUM(J105) | K20: =SUM(K105) | L20: =SUM(L105) | M20: =SUM(M105) | ... DB20: =SUM(DB105) | DD20: =SUM(F20:DB20)
A22: Total Monthly Project Costs | D22: =DD22 | F22: =SUM(F8:F20) | G22: =SUM(G8:G20) | H22: =SUM(H8:H20) | I22: =SUM(I8:I20) | J22: =SUM(J8:J20) | K22: =SUM(K8:K20) | L22: =SUM(L8:L20) | M22: =SUM(M8:M20) | ... DB22: =SUM(DB8:DB20) | DD22: =SUM(F22:DB22)
A24: Total Cumulative Project Costs | D24: =DD24 | F24: =F164 | G24: =G164 | H24: =H164 | I24: =I164 | J24: =J164 | K24: =K164 | L24: =L164 | M24: =M164 | ... DB24: =DB164 | DD24: =MIN(F24:DB24)
A27: Project Costs - Detailed Amounts
A29: Land or Building Purchase | B29: Purchase & Closing excl. Ground Lease | D29: =DD29 | F29: =-SUM('Detailed Project Costs'!$F$9:$F$12) | DD29: =SUM(F29:DB29)
A30: Land Development and Site Work | B30: Site Work | D30: =DD30 | F30: =IF('Project Assumptions'!$D$16<=3,0,IF(F5>'Project Assumptions'!$D$15,IF(F5<='Project Assumptions'!$D$15+3,-SUM('Detailed Project Costs'!$F$13:$F$15)/3,0),0))+IF('Project Assumptions'!$D$16>0,IF('Project Assumptions'!$D$16<=3,IF(F5='Project Assumptions'!$D$15+1,-SUM('Detailed Project Costs'!$F$13:$F$15),0),0),IF(F5='Project Assumptions'!$D$15,-SUM('Detailed Project Costs'!$F$13:$F$15),0)) | G30: =IF('Project Assumptions'!$D$16<=3,0,IF(G5>'Project Assumptions'!$D$15,IF(G5<='Project Assumptions'!$D$15+3,-SUM('Detailed Project Costs'!$F$13:$F$15)/3,0),0))+IF('Project Assumptions'!$D$16>0,IF('Project Assumptions'!$D$16<=3,IF(G5='Project Assumptions'!$D$15+1,-SUM('Detailed Project Costs'!$F$13:$F$15),0),0),IF(G5='Project Assumptions'!$D$15,-SUM('Detailed Project Costs'!$F$13:$F$15),0)) | H30: =IF('Project Assumptions'!$D$16<=3,0,IF(H5>'Project Assumptions'!$D$15,IF(H5<='Project Assumptions'!$D$15+3,-SUM('Detailed Project Costs'!$F$13:$F$15)/3,0),0))+IF('Project Assumptions'!$D$16>0,IF('Project Assumptions'!$D$16<=3,IF(H5='Project Assumptions'!$D$15+1,-SUM('Detailed Project Costs'!$F$13:$F$15),0),0),IF(H5='Project Assumptions'!$D$15,-SUM('Detailed Project Costs'!$F$13:$F$15),0)) | I30: =IF('Project Assumptions'!$D$16<=3,0,IF(I5>'Project Assumptions'!$D$15,IF(I5<='Project Assumptions'!$D$15+3,-SUM('Detailed Project Costs'!$F$13:$F$15)/3,0),0))+IF('Project Assumptions'!$D$16>0,IF('Project Assumptions'!$D$16<=3,IF(I5='Project Assumptions'!$D$15+1,-SUM('Detailed Project Costs'!$F$13:$F$15),0),0),IF(I5='Project Assumptions'!$D$15,-SUM('Detailed Project Costs'!$F$13:$F$15),0)) | J30: =IF('Project Assumptions'!$D$16<=3,0,IF(J5>'Project Assumptions'!$D$15,IF(J5<='Project Assumptions'!$D$15+3,-SUM('Detailed Project Costs'!$F$13:$F$15)/3,0),0))+IF('Project Assumptions'!$D$16>0,IF('Project Assumptions'!$D$16<=3,IF(J5='Project Assumptions'!$D$15+1,-SUM('Detailed Project Costs'!$F$13:$F$15),0),0),IF(J5='Project Assumptions'!$D$15,-SUM('Detailed Project Costs'!$F$13:$F$15),0)) | K30: =IF('Project Assumptions'!$D$16<=3,0,IF(K5>'Project Assumptions'!$D$15,IF(K5<='Project Assumptions'!$D$15+3,-SUM('Detailed Project Costs'!$F$13:$F$15)/3,0),0))+IF('Project Assumptions'!$D$16>0,IF('Project Assumptions'!$D$16<=3,IF(K5='Project Assumptions'!$D$15+1,-SUM('Detailed Project Costs'!$F$13:$F$15),0),0),IF(K5='Project Assumptions'!$D$15,-SUM('Detailed Project Costs'!$F$13:$F$15),0)) | L30: =IF('Project Assumptions'!$D$16<=3,0,IF(L5>'Project Assumptions'!$D$15,IF(L5<='Project Assumptions'!$D$15+3,-SUM('Detailed Project Costs'!$F$13:$F$15)/3,0),0))+IF('Project Assumptions'!$D$16>0,IF('Project Assumptions'!$D$16<=3,IF(L5='Project Assumptions'!$D$15+1,-SUM('Detailed Project Costs'!$F$13:$F$15),0),0),IF(L5='Project Assumptions'!$D$15,-SUM('Detailed Project Costs'!$F$13:$F$15),0)) | M30: =IF('Project Assumptions'!$D$16<=3,0,IF(M5>'Project Assumptions'!$D$15,IF(M5<='Project Assumptions'!$D$15+3,-SUM('Detailed Project Costs'!$F$13:$F$15)/3,0),0))+IF('Project Assumptions'!$D$16>0,IF('Project Assumptions'!$D$16<=3,IF(M5='Project Assumptions'!$D$15+1,-SUM('Detailed Project Costs'!$F$13:$F$15),0),0),IF(M5='Project Assumptions'!$D$15,-SUM('Detailed Project Costs'!$F$13:$F$15),0)) | ... DB30: =IF('Project Assumptions'!$D$16<=3,0,IF(DB5>'Project Assumptions'!$D$15,IF(DB5<='Project Assumptions'!$D$15+3,-SUM('Detailed Project Costs'!$F$13:$F$15)/3,0),0))+IF('Project Assumptions'!$D$16>0,IF('Project Assumptions'!$D$16<=3,IF(DB5='Project Assumptions'!$D$15+1,-SUM('Detailed Project Costs'!$F$13:$F$15),0),0),IF(DB5='Project Assumptions'!$D$15,-SUM('Detailed Project Costs'!$F$13:$F$15),0)) | DD30: =SUM(F30:DB30)
B31: Off-Site | D31: =DD31 | F31: =IF('Project Assumptions'!$D$16<=3,0,IF(F5>'Project Assumptions'!$D$15,IF(F5<='Project Assumptions'!$D$15+3,-SUM('Detailed Project Costs'!$F$16:$F$17)/3,0),0))+IF('Project Assumptions'!$D$16>0,IF('Project Assumptions'!$D$16<=3,IF(F5='Project Assumptions'!$D$15+1,-SUM('Detailed Project Costs'!$F$16:$F$17),0),0),IF(F5='Project Assumptions'!$D$15,-SUM('Detailed Project Costs'!$F$16:$F$17),0)) | G31: =IF('Project Assumptions'!$D$16<=3,0,IF(G5>'Project Assumptions'!$D$15,IF(G5<='Project Assumptions'!$D$15+3,-SUM('Detailed Project Costs'!$F$16:$F$17)/3,0),0))+IF('Project Assumptions'!$D$16>0,IF('Project Assumptions'!$D$16<=3,IF(G5='Project Assumptions'!$D$15+1,-SUM('Detailed Project Costs'!$F$16:$F$17),0),0),IF(G5='Project Assumptions'!$D$15,-SUM('Detailed Project Costs'!$F$16:$F$17),0)) | H31: =IF('Project Assumptions'!$D$16<=3,0,IF(H5>'Project Assumptions'!$D$15,IF(H5<='Project Assumptions'!$D$15+3,-SUM('Detailed Project Costs'!$F$16:$F$17)/3,0),0))+IF('Project Assumptions'!$D$16>0,IF('Project Assumptions'!$D$16<=3,IF(H5='Project Assumptions'!$D$15+1,-SUM('Detailed Project Costs'!$F$16:$F$17),0),0),IF(H5='Project Assumptions'!$D$15,-SUM('Detailed Project Costs'!$F$16:$F$17),0)) | I31: =IF('Project Assumptions'!$D$16<=3,0,IF(I5>'Project Assumptions'!$D$15,IF(I5<='Project Assumptions'!$D$15+3,-SUM('Detailed Project Costs'!$F$16:$F$17)/3,0),0))+IF('Project Assumptions'!$D$16>0,IF('Project Assumptions'!$D$16<=3,IF(I5='Project Assumptions'!$D$15+1,-SUM('Detailed Project Costs'!$F$16:$F$17),0),0),IF(I5='Project Assumptions'!$D$15,-SUM('Detailed Project Costs'!$F$16:$F$17),0)) | J31: =IF('Project Assumptions'!$D$16<=3,0,IF(J5>'Project Assumptions'!$D$15,IF(J5<='Project Assumptions'!$D$15+3,-SUM('Detailed Project Costs'!$F$16:$F$17)/3,0),0))+IF('Project Assumptions'!$D$16>0,IF('Project Assumptions'!$D$16<=3,IF(J5='Project Assumptions'!$D$15+1,-SUM('Detailed Project Costs'!$F$16:$F$17),0),0),IF(J5='Project Assumptions'!$D$15,-SUM('Detailed Project Costs'!$F$16:$F$17),0)) | K31: =IF('Project Assumptions'!$D$16<=3,0,IF(K5>'Project Assumptions'!$D$15,IF(K5<='Project Assumptions'!$D$15+3,-SUM('Detailed Project Costs'!$F$16:$F$17)/3,0),0))+IF('Project Assumptions'!$D$16>0,IF('Project Assumptions'!$D$16<=3,IF(K5='Project Assumptions'!$D$15+1,-SUM('Detailed Project Costs'!$F$16:$F$17),0),0),IF(K5='Project Assumptions'!$D$15,-SUM('Detailed Project Costs'!$F$16:$F$17),0)) | L31: =IF('Project Assumptions'!$D$16<=3,0,IF(L5>'Project Assumptions'!$D$15,IF(L5<='Project Assumptions'!$D$15+3,-SUM('Detailed Project Costs'!$F$16:$F$17)/3,0),0))+IF('Project Assumptions'!$D$16>0,IF('Project Assumptions'!$D$16<=3,IF(L5='Project Assumptions'!$D$15+1,-SUM('Detailed Project Costs'!$F$16:$F$17),0),0),IF(L5='Project Assumptions'!$D$15,-SUM('Detailed Project Costs'!$F$16:$F$17),0)) | M31: =IF('Project Assumptions'!$D$16<=3,0,IF(M5>'Project Assumptions'!$D$15,IF(M5<='Project Assumptions'!$D$15+3,-SUM('Detailed Project Costs'!$F$16:$F$17)/3,0),0))+IF('Project Assumptions'!$D$16>0,IF('Project Assumptions'!$D$16<=3,IF(M5='Project Assumptions'!$D$15+1,-SUM('Detailed Project Costs'!$F$16:$F$17),0),0),IF(M5='Project Assumptions'!$D$15,-SUM('Detailed Project Costs'!$F$16:$F$17),0)) | ... DB31: =IF('Project Assumptions'!$D$16<=3,0,IF(DB5>'Project Assumptions'!$D$15,IF(DB5<='Project Assumptions'!$D$15+3,-SUM('Detailed Project Costs'!$F$16:$F$17)/3,0),0))+IF('Project Assumptions'!$D$16>0,IF('Project Assumptions'!$D$16<=3,IF(DB5='Project Assumptions'!$D$15+1,-SUM('Detailed Project Costs'!$F$16:$F$17),0),0),IF(DB5='Project Assumptions'!$D$15,-SUM('Detailed Project Costs'!$F$16:$F$17),0)) | DD31: =SUM(F31:DB31)
B32: Landscaping and Irrigation | D32: =DD32 | F32: =+IF(F5='Project Assumptions'!$D$15+'Project Assumptions'!$D$16,-SUM('Detailed Project Costs'!$F$18:$F$19),0) | G32: =+IF(G5='Project Assumptions'!$D$15+'Project Assumptions'!$D$16,-SUM('Detailed Project Costs'!$F$18:$F$19),0) | H32: =+IF(H5='Project Assumptions'!$D$15+'Project Assumptions'!$D$16,-SUM('Detailed Project Costs'!$F$18:$F$19),0) | I32: =+IF(I5='Project Assumptions'!$D$15+'Project Assumptions'!$D$16,-SUM('Detailed Project Costs'!$F$18:$F$19),0) | J32: =+IF(J5='Project Assumptions'!$D$15+'Project Assumptions'!$D$16,-SUM('Detailed Project Costs'!$F$18:$F$19),0) | K32: =+IF(K5='Project Assumptions'!$D$15+'Project Assumptions'!$D$16,-SUM('Detailed Project Costs'!$F$18:$F$19),0) | L32: =+IF(L5='Project Assumptions'!$D$15+'Project Assumptions'!$D$16,-SUM('Detailed Project Costs'!$F$18:$F$19),0) | M32: =+IF(M5='Project Assumptions'!$D$15+'Project Assumptions'!$D$16,-SUM('Detailed Project Costs'!$F$18:$F$19),0) | ... DB32: =+IF(DB5='Project Assumptions'!$D$15+'Project Assumptions'!$D$16,-SUM('Detailed Project Costs'!$F$18:$F$19),0) | DD32: =SUM(F32:DB32)
A33: Building Shell | B33: Building Shell | D33: =DD33 | F33: =IF(F5>'Project Assumptions'!$D$15,IF(F5<='Project Assumptions'!$D$15+'Project Assumptions'!$D$16,-SUM('Detailed Project Costs'!$F$20:$F$22)/'Project Assumptions'!$D$16,0),0)+IF('Project Assumptions'!$D$16=0,IF(F5='Project Assumptions'!$D$15,-SUM('Detailed Project Costs'!$F$20:$F$22),0),0) | G33: =IF(G5>'Project Assumptions'!$D$15,IF(G5<='Project Assumptions'!$D$15+'Project Assumptions'!$D$16,-SUM('Detailed Project Costs'!$F$20:$F$22)/'Project Assumptions'!$D$16,0),0)+IF('Project Assumptions'!$D$16=0,IF(G5='Project Assumptions'!$D$15,-SUM('Detailed Project Costs'!$F$20:$F$22),0),0) | H33: =IF(H5>'Project Assumptions'!$D$15,IF(H5<='Project Assumptions'!$D$15+'Project Assumptions'!$D$16,-SUM('Detailed Project Costs'!$F$20:$F$22)/'Project Assumptions'!$D$16,0),0)+IF('Project Assumptions'!$D$16=0,IF(H5='Project Assumptions'!$D$15,-SUM('Detailed Project Costs'!$F$20:$F$22),0),0) | I33: =IF(I5>'Project Assumptions'!$D$15,IF(I5<='Project Assumptions'!$D$15+'Project Assumptions'!$D$16,-SUM('Detailed Project Costs'!$F$20:$F$22)/'Project Assumptions'!$D$16,0),0)+IF('Project Assumptions'!$D$16=0,IF(I5='Project Assumptions'!$D$15,-SUM('Detailed Project Costs'!$F$20:$F$22),0),0) | J33: =IF(J5>'Project Assumptions'!$D$15,IF(J5<='Project Assumptions'!$D$15+'Project Assumptions'!$D$16,-SUM('Detailed Project Costs'!$F$20:$F$22)/'Project Assumptions'!$D$16,0),0)+IF('Project Assumptions'!$D$16=0,IF(J5='Project Assumptions'!$D$15,-SUM('Detailed Project Costs'!$F$20:$F$22),0),0) | K33: =IF(K5>'Project Assumptions'!$D$15,IF(K5<='Project Assumptions'!$D$15+'Project Assumptions'!$D$16,-SUM('Detailed Project Costs'!$F$20:$F$22)/'Project Assumptions'!$D$16,0),0)+IF('Project Assumptions'!$D$16=0,IF(K5='Project Assumptions'!$D$15,-SUM('Detailed Project Costs'!$F$20:$F$22),0),0) | L33: =IF(L5>'Project Assumptions'!$D$15,IF(L5<='Project Assumptions'!$D$15+'Project Assumptions'!$D$16,-SUM('Detailed Project Costs'!$F$20:$F$22)/'Project Assumptions'!$D$16,0),0)+IF('Project Assumptions'!$D$16=0,IF(L5='Project Assumptions'!$D$15,-SUM('Detailed Project Costs'!$F$20:$F$22),0),0) | M33: =IF(M5>'Project Assumptions'!$D$15,IF(M5<='Project Assumptions'!$D$15+'Project Assumptions'!$D$16,-SUM('Detailed Project Costs'!$F$20:$F$22)/'Project Assumptions'!$D$16,0),0)+IF('Project Assumptions'!$D$16=0,IF(M5='Project Assumptions'!$D$15,-SUM('Detailed Project Costs'!$F$20:$F$22),0),0) | ... DB33: =IF(DB5>'Project Assumptions'!$D$15,IF(DB5<='Project Assumptions'!$D$15+'Project Assumptions'!$D$16,-SUM('Detailed Project Costs'!$F$20:$F$22)/'Project Assumptions'!$D$16,0),0)+IF('Project Assumptions'!$D$16=0,IF(DB5='Project Assumptions'!$D$15,-SUM('Detailed Project Costs'!$F$20:$F$22),0),0) | DD33: =SUM(F33:DB33)
B34: Structured Parking | D34: =DD34 | F34: =IF(F5>'Project Assumptions'!$D$15,IF(F5<='Project Assumptions'!$D$15+'Project Assumptions'!$D$16,-SUM('Detailed Project Costs'!$F$23:$F$24)/'Project Assumptions'!$D$16,0),0)+IF('Project Assumptions'!$D$16=0,IF(F5='Project Assumptions'!$D$15,-SUM('Detailed Project Costs'!$F$23:$F$24),0),0) | G34: =IF(G5>'Project Assumptions'!$D$15,IF(G5<='Project Assumptions'!$D$15+'Project Assumptions'!$D$16,-SUM('Detailed Project Costs'!$F$23:$F$24)/'Project Assumptions'!$D$16,0),0)+IF('Project Assumptions'!$D$16=0,IF(G5='Project Assumptions'!$D$15,-SUM('Detailed Project Costs'!$F$23:$F$24),0),0) | H34: =IF(H5>'Project Assumptions'!$D$15,IF(H5<='Project Assumptions'!$D$15+'Project Assumptions'!$D$16,-SUM('Detailed Project Costs'!$F$23:$F$24)/'Project Assumptions'!$D$16,0),0)+IF('Project Assumptions'!$D$16=0,IF(H5='Project Assumptions'!$D$15,-SUM('Detailed Project Costs'!$F$23:$F$24),0),0) | I34: =IF(I5>'Project Assumptions'!$D$15,IF(I5<='Project Assumptions'!$D$15+'Project Assumptions'!$D$16,-SUM('Detailed Project Costs'!$F$23:$F$24)/'Project Assumptions'!$D$16,0),0)+IF('Project Assumptions'!$D$16=0,IF(I5='Project Assumptions'!$D$15,-SUM('Detailed Project Costs'!$F$23:$F$24),0),0) | J34: =IF(J5>'Project Assumptions'!$D$15,IF(J5<='Project Assumptions'!$D$15+'Project Assumptions'!$D$16,-SUM('Detailed Project Costs'!$F$23:$F$24)/'Project Assumptions'!$D$16,0),0)+IF('Project Assumptions'!$D$16=0,IF(J5='Project Assumptions'!$D$15,-SUM('Detailed Project Costs'!$F$23:$F$24),0),0) | K34: =IF(K5>'Project Assumptions'!$D$15,IF(K5<='Project Assumptions'!$D$15+'Project Assumptions'!$D$16,-SUM('Detailed Project Costs'!$F$23:$F$24)/'Project Assumptions'!$D$16,0),0)+IF('Project Assumptions'!$D$16=0,IF(K5='Project Assumptions'!$D$15,-SUM('Detailed Project Costs'!$F$23:$F$24),0),0) | L34: =IF(L5>'Project Assumptions'!$D$15,IF(L5<='Project Assumptions'!$D$15+'Project Assumptions'!$D$16,-SUM('Detailed Project Costs'!$F$23:$F$24)/'Project Assumptions'!$D$16,0),0)+IF('Project Assumptions'!$D$16=0,IF(L5='Project Assumptions'!$D$15,-SUM('Detailed Project Costs'!$F$23:$F$24),0),0) | M34: =IF(M5>'Project Assumptions'!$D$15,IF(M5<='Project Assumptions'!$D$15+'Project Assumptions'!$D$16,-SUM('Detailed Project Costs'!$F$23:$F$24)/'Project Assumptions'!$D$16,0),0)+IF('Project Assumptions'!$D$16=0,IF(M5='Project Assumptions'!$D$15,-SUM('Detailed Project Costs'!$F$23:$F$24),0),0) | ... DB34: =IF(DB5>'Project Assumptions'!$D$15,IF(DB5<='Project Assumptions'!$D$15+'Project Assumptions'!$D$16,-SUM('Detailed Project Costs'!$F$23:$F$24)/'Project Assumptions'!$D$16,0),0)+IF('Project Assumptions'!$D$16=0,IF(DB5='Project Assumptions'!$D$15,-SUM('Detailed Project Costs'!$F$23:$F$24),0),0) | DD34: =SUM(F34:DB34)
A35: Tenant Improvements | B35: Hard Costs | D35: =DD35 | F35: =SUM(F36:F45) | G35: =SUM(G36:G45) | H35: =SUM(H36:H45) | I35: =SUM(I36:I45) | J35: =SUM(J36:J45) | K35: =SUM(K36:K45) | L35: =SUM(L36:L45) | M35: =SUM(M36:M45) | ... DB35: =SUM(DB36:DB45) | DD35: =SUM(F35:DB35)
B36: ='Economic Assumptions'!$A$10 | D36: =DD36 | F36: =IF('Economic Assumptions'!$B10+'Project Assumptions'!$D$15+'Project Assumptions'!$D$16-1='Detailed Cashflows'!F$5,-'Economic Assumptions'!$C10*'Economic Assumptions'!$K10,0) | G36: =IF('Economic Assumptions'!$B10+'Project Assumptions'!$D$15+'Project Assumptions'!$D$16-1='Detailed Cashflows'!G$5,-'Economic Assumptions'!$C10*'Economic Assumptions'!$K10,0) | H36: =IF('Economic Assumptions'!$B10+'Project Assumptions'!$D$15+'Project Assumptions'!$D$16-1='Detailed Cashflows'!H$5,-'Economic Assumptions'!$C10*'Economic Assumptions'!$K10,0) | I36: =IF('Economic Assumptions'!$B10+'Project Assumptions'!$D$15+'Project Assumptions'!$D$16-1='Detailed Cashflows'!I$5,-'Economic Assumptions'!$C10*'Economic Assumptions'!$K10,0) | J36: =IF('Economic Assumptions'!$B10+'Project Assumptions'!$D$15+'Project Assumptions'!$D$16-1='Detailed Cashflows'!J$5,-'Economic Assumptions'!$C10*'Economic Assumptions'!$K10,0) | K36: =IF('Economic Assumptions'!$B10+'Project Assumptions'!$D$15+'Project Assumptions'!$D$16-1='Detailed Cashflows'!K$5,-'Economic Assumptions'!$C10*'Economic Assumptions'!$K10,0) | L36: =IF('Economic Assumptions'!$B10+'Project Assumptions'!$D$15+'Project Assumptions'!$D$16-1='Detailed Cashflows'!L$5,-'Economic Assumptions'!$C10*'Economic Assumptions'!$K10,0) | M36: =IF('Economic Assumptions'!$B10+'Project Assumptions'!$D$15+'Project Assumptions'!$D$16-1='Detailed Cashflows'!M$5,-'Economic Assumptions'!$C10*'Economic Assumptions'!$K10,0) | ... DB36: =IF('Economic Assumptions'!$B10+'Project Assumptions'!$D$15+'Project Assumptions'!$D$16-1='Detailed Cashflows'!DB$5,-'Economic Assumptions'!$C10*'Economic Assumptions'!$K10,0) | DD36: =SUM(F36:DB36)
B37: ='Economic Assumptions'!$A$11 | D37: =DD37 | F37: =IF('Economic Assumptions'!$B11+'Project Assumptions'!$D$15+'Project Assumptions'!$D$16-1='Detailed Cashflows'!F$5,-'Economic Assumptions'!$C11*'Economic Assumptions'!$K11,0) | G37: =IF('Economic Assumptions'!$B11+'Project Assumptions'!$D$15+'Project Assumptions'!$D$16-1='Detailed Cashflows'!G$5,-'Economic Assumptions'!$C11*'Economic Assumptions'!$K11,0) | H37: =IF('Economic Assumptions'!$B11+'Project Assumptions'!$D$15+'Project Assumptions'!$D$16-1='Detailed Cashflows'!H$5,-'Economic Assumptions'!$C11*'Economic Assumptions'!$K11,0) | I37: =IF('Economic Assumptions'!$B11+'Project Assumptions'!$D$15+'Project Assumptions'!$D$16-1='Detailed Cashflows'!I$5,-'Economic Assumptions'!$C11*'Economic Assumptions'!$K11,0) | J37: =IF('Economic Assumptions'!$B11+'Project Assumptions'!$D$15+'Project Assumptions'!$D$16-1='Detailed Cashflows'!J$5,-'Economic Assumptions'!$C11*'Economic Assumptions'!$K11,0) | K37: =IF('Economic Assumptions'!$B11+'Project Assumptions'!$D$15+'Project Assumptions'!$D$16-1='Detailed Cashflows'!K$5,-'Economic Assumptions'!$C11*'Economic Assumptions'!$K11,0) | L37: =IF('Economic Assumptions'!$B11+'Project Assumptions'!$D$15+'Project Assumptions'!$D$16-1='Detailed Cashflows'!L$5,-'Economic Assumptions'!$C11*'Economic Assumptions'!$K11,0) | M37: =IF('Economic Assumptions'!$B11+'Project Assumptions'!$D$15+'Project Assumptions'!$D$16-1='Detailed Cashflows'!M$5,-'Economic Assumptions'!$C11*'Economic Assumptions'!$K11,0) | ... DB37: =IF('Economic Assumptions'!$B11+'Project Assumptions'!$D$15+'Project Assumptions'!$D$16-1='Detailed Cashflows'!DB$5,-'Economic Assumptions'!$C11*'Economic Assumptions'!$K11,0) | DD37: =SUM(F37:DB37)
B38: ='Economic Assumptions'!$A$12 | D38: =DD38 | F38: =IF('Economic Assumptions'!$B12+'Project Assumptions'!$D$15+'Project Assumptions'!$D$16-1='Detailed Cashflows'!F$5,-'Economic Assumptions'!$C12*'Economic Assumptions'!$K12,0) | G38: =IF('Economic Assumptions'!$B12+'Project Assumptions'!$D$15+'Project Assumptions'!$D$16-1='Detailed Cashflows'!G$5,-'Economic Assumptions'!$C12*'Economic Assumptions'!$K12,0) | H38: =IF('Economic Assumptions'!$B12+'Project Assumptions'!$D$15+'Project Assumptions'!$D$16-1='Detailed Cashflows'!H$5,-'Economic Assumptions'!$C12*'Economic Assumptions'!$K12,0) | I38: =IF('Economic Assumptions'!$B12+'Project Assumptions'!$D$15+'Project Assumptions'!$D$16-1='Detailed Cashflows'!I$5,-'Economic Assumptions'!$C12*'Economic Assumptions'!$K12,0) | J38: =IF('Economic Assumptions'!$B12+'Project Assumptions'!$D$15+'Project Assumptions'!$D$16-1='Detailed Cashflows'!J$5,-'Economic Assumptions'!$C12*'Economic Assumptions'!$K12,0) | K38: =IF('Economic Assumptions'!$B12+'Project Assumptions'!$D$15+'Project Assumptions'!$D$16-1='Detailed Cashflows'!K$5,-'Economic Assumptions'!$C12*'Economic Assumptions'!$K12,0) | L38: =IF('Economic Assumptions'!$B12+'Project Assumptions'!$D$15+'Project Assumptions'!$D$16-1='Detailed Cashflows'!L$5,-'Economic Assumptions'!$C12*'Economic Assumptions'!$K12,0) | M38: =IF('Economic Assumptions'!$B12+'Project Assumptions'!$D$15+'Project Assumptions'!$D$16-1='Detailed Cashflows'!M$5,-'Economic Assumptions'!$C12*'Economic Assumptions'!$K12,0) | ... DB38: =IF('Economic Assumptions'!$B12+'Project Assumptions'!$D$15+'Project Assumptions'!$D$16-1='Detailed Cashflows'!DB$5,-'Economic Assumptions'!$C12*'Economic Assumptions'!$K12,0) | DD38: =SUM(F38:DB38)
B39: ='Economic Assumptions'!$A$13 | D39: =DD39 | F39: =IF('Economic Assumptions'!$B13+'Project Assumptions'!$D$15+'Project Assumptions'!$D$16-1='Detailed Cashflows'!F$5,-'Economic Assumptions'!$C13*'Economic Assumptions'!$K13,0) | G39: =IF('Economic Assumptions'!$B13+'Project Assumptions'!$D$15+'Project Assumptions'!$D$16-1='Detailed Cashflows'!G$5,-'Economic Assumptions'!$C13*'Economic Assumptions'!$K13,0) | H39: =IF('Economic Assumptions'!$B13+'Project Assumptions'!$D$15+'Project Assumptions'!$D$16-1='Detailed Cashflows'!H$5,-'Economic Assumptions'!$C13*'Economic Assumptions'!$K13,0) | I39: =IF('Economic Assumptions'!$B13+'Project Assumptions'!$D$15+'Project Assumptions'!$D$16-1='Detailed Cashflows'!I$5,-'Economic Assumptions'!$C13*'Economic Assumptions'!$K13,0) | J39: =IF('Economic Assumptions'!$B13+'Project Assumptions'!$D$15+'Project Assumptions'!$D$16-1='Detailed Cashflows'!J$5,-'Economic Assumptions'!$C13*'Economic Assumptions'!$K13,0) | K39: =IF('Economic Assumptions'!$B13+'Project Assumptions'!$D$15+'Project Assumptions'!$D$16-1='Detailed Cashflows'!K$5,-'Economic Assumptions'!$C13*'Economic Assumptions'!$K13,0) | L39: =IF('Economic Assumptions'!$B13+'Project Assumptions'!$D$15+'Project Assumptions'!$D$16-1='Detailed Cashflows'!L$5,-'Economic Assumptions'!$C13*'Economic Assumptions'!$K13,0) | M39: =IF('Economic Assumptions'!$B13+'Project Assumptions'!$D$15+'Project Assumptions'!$D$16-1='Detailed Cashflows'!M$5,-'Economic Assumptions'!$C13*'Economic Assumptions'!$K13,0) | ... DB39: =IF('Economic Assumptions'!$B13+'Project Assumptions'!$D$15+'Project Assumptions'!$D$16-1='Detailed Cashflows'!DB$5,-'Economic Assumptions'!$C13*'Economic Assumptions'!$K13,0) | DD39: =SUM(F39:DB39)
B40: ='Economic Assumptions'!$A$14 | D40: =DD40 | F40: =IF('Economic Assumptions'!$B14+'Project Assumptions'!$D$15+'Project Assumptions'!$D$16-1='Detailed Cashflows'!F$5,-'Economic Assumptions'!$C14*'Economic Assumptions'!$K14,0) | G40: =IF('Economic Assumptions'!$B14+'Project Assumptions'!$D$15+'Project Assumptions'!$D$16-1='Detailed Cashflows'!G$5,-'Economic Assumptions'!$C14*'Economic Assumptions'!$K14,0) | H40: =IF('Economic Assumptions'!$B14+'Project Assumptions'!$D$15+'Project Assumptions'!$D$16-1='Detailed Cashflows'!H$5,-'Economic Assumptions'!$C14*'Economic Assumptions'!$K14,0) | I40: =IF('Economic Assumptions'!$B14+'Project Assumptions'!$D$15+'Project Assumptions'!$D$16-1='Detailed Cashflows'!I$5,-'Economic Assumptions'!$C14*'Economic Assumptions'!$K14,0) | J40: =IF('Economic Assumptions'!$B14+'Project Assumptions'!$D$15+'Project Assumptions'!$D$16-1='Detailed Cashflows'!J$5,-'Economic Assumptions'!$C14*'Economic Assumptions'!$K14,0) | K40: =IF('Economic Assumptions'!$B14+'Project Assumptions'!$D$15+'Project Assumptions'!$D$16-1='Detailed Cashflows'!K$5,-'Economic Assumptions'!$C14*'Economic Assumptions'!$K14,0) | L40: =IF('Economic Assumptions'!$B14+'Project Assumptions'!$D$15+'Project Assumptions'!$D$16-1='Detailed Cashflows'!L$5,-'Economic Assumptions'!$C14*'Economic Assumptions'!$K14,0) | M40: =IF('Economic Assumptions'!$B14+'Project Assumptions'!$D$15+'Project Assumptions'!$D$16-1='Detailed Cashflows'!M$5,-'Economic Assumptions'!$C14*'Economic Assumptions'!$K14,0) | ... DB40: =IF('Economic Assumptions'!$B14+'Project Assumptions'!$D$15+'Project Assumptions'!$D$16-1='Detailed Cashflows'!DB$5,-'Economic Assumptions'!$C14*'Economic Assumptions'!$K14,0) | DD40: =SUM(F40:DB40)
B41: ='Economic Assumptions'!$A$15 | D41: =DD41 | F41: =IF('Economic Assumptions'!$B15+'Project Assumptions'!$D$15+'Project Assumptions'!$D$16-1='Detailed Cashflows'!F$5,-'Economic Assumptions'!$C15*'Economic Assumptions'!$K15,0) | G41: =IF('Economic Assumptions'!$B15+'Project Assumptions'!$D$15+'Project Assumptions'!$D$16-1='Detailed Cashflows'!G$5,-'Economic Assumptions'!$C15*'Economic Assumptions'!$K15,0) | H41: =IF('Economic Assumptions'!$B15+'Project Assumptions'!$D$15+'Project Assumptions'!$D$16-1='Detailed Cashflows'!H$5,-'Economic Assumptions'!$C15*'Economic Assumptions'!$K15,0) | I41: =IF('Economic Assumptions'!$B15+'Project Assumptions'!$D$15+'Project Assumptions'!$D$16-1='Detailed Cashflows'!I$5,-'Economic Assumptions'!$C15*'Economic Assumptions'!$K15,0) | J41: =IF('Economic Assumptions'!$B15+'Project Assumptions'!$D$15+'Project Assumptions'!$D$16-1='Detailed Cashflows'!J$5,-'Economic Assumptions'!$C15*'Economic Assumptions'!$K15,0) | K41: =IF('Economic Assumptions'!$B15+'Project Assumptions'!$D$15+'Project Assumptions'!$D$16-1='Detailed Cashflows'!K$5,-'Economic Assumptions'!$C15*'Economic Assumptions'!$K15,0) | L41: =IF('Economic Assumptions'!$B15+'Project Assumptions'!$D$15+'Project Assumptions'!$D$16-1='Detailed Cashflows'!L$5,-'Economic Assumptions'!$C15*'Economic Assumptions'!$K15,0) | M41: =IF('Economic Assumptions'!$B15+'Project Assumptions'!$D$15+'Project Assumptions'!$D$16-1='Detailed Cashflows'!M$5,-'Economic Assumptions'!$C15*'Economic Assumptions'!$K15,0) | ... DB41: =IF('Economic Assumptions'!$B15+'Project Assumptions'!$D$15+'Project Assumptions'!$D$16-1='Detailed Cashflows'!DB$5,-'Economic Assumptions'!$C15*'Economic Assumptions'!$K15,0) | DD41: =SUM(F41:DB41)
B42: ='Economic Assumptions'!$A$16 | D42: =DD42 | F42: =IF('Economic Assumptions'!$B16+'Project Assumptions'!$D$15+'Project Assumptions'!$D$16-1='Detailed Cashflows'!F$5,-'Economic Assumptions'!$C16*'Economic Assumptions'!$K16,0) | G42: =IF('Economic Assumptions'!$B16+'Project Assumptions'!$D$15+'Project Assumptions'!$D$16-1='Detailed Cashflows'!G$5,-'Economic Assumptions'!$C16*'Economic Assumptions'!$K16,0) | H42: =IF('Economic Assumptions'!$B16+'Project Assumptions'!$D$15+'Project Assumptions'!$D$16-1='Detailed Cashflows'!H$5,-'Economic Assumptions'!$C16*'Economic Assumptions'!$K16,0) | I42: =IF('Economic Assumptions'!$B16+'Project Assumptions'!$D$15+'Project Assumptions'!$D$16-1='Detailed Cashflows'!I$5,-'Economic Assumptions'!$C16*'Economic Assumptions'!$K16,0) | J42: =IF('Economic Assumptions'!$B16+'Project Assumptions'!$D$15+'Project Assumptions'!$D$16-1='Detailed Cashflows'!J$5,-'Economic Assumptions'!$C16*'Economic Assumptions'!$K16,0) | K42: =IF('Economic Assumptions'!$B16+'Project Assumptions'!$D$15+'Project Assumptions'!$D$16-1='Detailed Cashflows'!K$5,-'Economic Assumptions'!$C16*'Economic Assumptions'!$K16,0) | L42: =IF('Economic Assumptions'!$B16+'Project Assumptions'!$D$15+'Project Assumptions'!$D$16-1='Detailed Cashflows'!L$5,-'Economic Assumptions'!$C16*'Economic Assumptions'!$K16,0) | M42: =IF('Economic Assumptions'!$B16+'Project Assumptions'!$D$15+'Project Assumptions'!$D$16-1='Detailed Cashflows'!M$5,-'Economic Assumptions'!$C16*'Economic Assumptions'!$K16,0) | ... DB42: =IF('Economic Assumptions'!$B16+'Project Assumptions'!$D$15+'Project Assumptions'!$D$16-1='Detailed Cashflows'!DB$5,-'Economic Assumptions'!$C16*'Economic Assumptions'!$K16,0) | DD42: =SUM(F42:DB42)
B43: ='Economic Assumptions'!$A$17 | D43: =DD43 | F43: =IF('Economic Assumptions'!$B17+'Project Assumptions'!$D$15+'Project Assumptions'!$D$16-1='Detailed Cashflows'!F$5,-'Economic Assumptions'!$C17*'Economic Assumptions'!$K17,0) | G43: =IF('Economic Assumptions'!$B17+'Project Assumptions'!$D$15+'Project Assumptions'!$D$16-1='Detailed Cashflows'!G$5,-'Economic Assumptions'!$C17*'Economic Assumptions'!$K17,0) | H43: =IF('Economic Assumptions'!$B17+'Project Assumptions'!$D$15+'Project Assumptions'!$D$16-1='Detailed Cashflows'!H$5,-'Economic Assumptions'!$C17*'Economic Assumptions'!$K17,0) | I43: =IF('Economic Assumptions'!$B17+'Project Assumptions'!$D$15+'Project Assumptions'!$D$16-1='Detailed Cashflows'!I$5,-'Economic Assumptions'!$C17*'Economic Assumptions'!$K17,0) | J43: =IF('Economic Assumptions'!$B17+'Project Assumptions'!$D$15+'Project Assumptions'!$D$16-1='Detailed Cashflows'!J$5,-'Economic Assumptions'!$C17*'Economic Assumptions'!$K17,0) | K43: =IF('Economic Assumptions'!$B17+'Project Assumptions'!$D$15+'Project Assumptions'!$D$16-1='Detailed Cashflows'!K$5,-'Economic Assumptions'!$C17*'Economic Assumptions'!$K17,0) | L43: =IF('Economic Assumptions'!$B17+'Project Assumptions'!$D$15+'Project Assumptions'!$D$16-1='Detailed Cashflows'!L$5,-'Economic Assumptions'!$C17*'Economic Assumptions'!$K17,0) | M43: =IF('Economic Assumptions'!$B17+'Project Assumptions'!$D$15+'Project Assumptions'!$D$16-1='Detailed Cashflows'!M$5,-'Economic Assumptions'!$C17*'Economic Assumptions'!$K17,0) | ... DB43: =IF('Economic Assumptions'!$B17+'Project Assumptions'!$D$15+'Project Assumptions'!$D$16-1='Detailed Cashflows'!DB$5,-'Economic Assumptions'!$C17*'Economic Assumptions'!$K17,0) | DD43: =SUM(F43:DB43)
B44: ='Economic Assumptions'!$A$18 | D44: =DD44 | F44: =IF('Economic Assumptions'!$B18+'Project Assumptions'!$D$15+'Project Assumptions'!$D$16-1='Detailed Cashflows'!F$5,-'Economic Assumptions'!$C18*'Economic Assumptions'!$K18,0) | G44: =IF('Economic Assumptions'!$B18+'Project Assumptions'!$D$15+'Project Assumptions'!$D$16-1='Detailed Cashflows'!G$5,-'Economic Assumptions'!$C18*'Economic Assumptions'!$K18,0) | H44: =IF('Economic Assumptions'!$B18+'Project Assumptions'!$D$15+'Project Assumptions'!$D$16-1='Detailed Cashflows'!H$5,-'Economic Assumptions'!$C18*'Economic Assumptions'!$K18,0) | I44: =IF('Economic Assumptions'!$B18+'Project Assumptions'!$D$15+'Project Assumptions'!$D$16-1='Detailed Cashflows'!I$5,-'Economic Assumptions'!$C18*'Economic Assumptions'!$K18,0) | J44: =IF('Economic Assumptions'!$B18+'Project Assumptions'!$D$15+'Project Assumptions'!$D$16-1='Detailed Cashflows'!J$5,-'Economic Assumptions'!$C18*'Economic Assumptions'!$K18,0) | K44: =IF('Economic Assumptions'!$B18+'Project Assumptions'!$D$15+'Project Assumptions'!$D$16-1='Detailed Cashflows'!K$5,-'Economic Assumptions'!$C18*'Economic Assumptions'!$K18,0) | L44: =IF('Economic Assumptions'!$B18+'Project Assumptions'!$D$15+'Project Assumptions'!$D$16-1='Detailed Cashflows'!L$5,-'Economic Assumptions'!$C18*'Economic Assumptions'!$K18,0) | M44: =IF('Economic Assumptions'!$B18+'Project Assumptions'!$D$15+'Project Assumptions'!$D$16-1='Detailed Cashflows'!M$5,-'Economic Assumptions'!$C18*'Economic Assumptions'!$K18,0) | ... DB44: =IF('Economic Assumptions'!$B18+'Project Assumptions'!$D$15+'Project Assumptions'!$D$16-1='Detailed Cashflows'!DB$5,-'Economic Assumptions'!$C18*'Economic Assumptions'!$K18,0) | DD44: =SUM(F44:DB44)
B45: ='Economic Assumptions'!$A$19 | D45: =DD45 | F45: =IF('Economic Assumptions'!$B19+'Project Assumptions'!$D$15+'Project Assumptions'!$D$16-1='Detailed Cashflows'!F$5,-'Economic Assumptions'!$C19*'Economic Assumptions'!$K19,0) | G45: =IF('Economic Assumptions'!$B19+'Project Assumptions'!$D$15+'Project Assumptions'!$D$16-1='Detailed Cashflows'!G$5,-'Economic Assumptions'!$C19*'Economic Assumptions'!$K19,0) | H45: =IF('Economic Assumptions'!$B19+'Project Assumptions'!$D$15+'Project Assumptions'!$D$16-1='Detailed Cashflows'!H$5,-'Economic Assumptions'!$C19*'Economic Assumptions'!$K19,0) | I45: =IF('Economic Assumptions'!$B19+'Project Assumptions'!$D$15+'Project Assumptions'!$D$16-1='Detailed Cashflows'!I$5,-'Economic Assumptions'!$C19*'Economic Assumptions'!$K19,0) | J45: =IF('Economic Assumptions'!$B19+'Project Assumptions'!$D$15+'Project Assumptions'!$D$16-1='Detailed Cashflows'!J$5,-'Economic Assumptions'!$C19*'Economic Assumptions'!$K19,0) | K45: =IF('Economic Assumptions'!$B19+'Project Assumptions'!$D$15+'Project Assumptions'!$D$16-1='Detailed Cashflows'!K$5,-'Economic Assumptions'!$C19*'Economic Assumptions'!$K19,0) | L45: =IF('Economic Assumptions'!$B19+'Project Assumptions'!$D$15+'Project Assumptions'!$D$16-1='Detailed Cashflows'!L$5,-'Economic Assumptions'!$C19*'Economic Assumptions'!$K19,0) | M45: =IF('Economic Assumptions'!$B19+'Project Assumptions'!$D$15+'Project Assumptions'!$D$16-1='Detailed Cashflows'!M$5,-'Economic Assumptions'!$C19*'Economic Assumptions'!$K19,0) | ... DB45: =IF('Economic Assumptions'!$B19+'Project Assumptions'!$D$15+'Project Assumptions'!$D$16-1='Detailed Cashflows'!DB$5,-'Economic Assumptions'!$C19*'Economic Assumptions'!$K19,0) | DD45: =SUM(F45:DB45)
B46: Soft Costs | D46: =DD46 | F46: =SUM(F47:F56) | G46: =SUM(G47:G56) | H46: =SUM(H47:H56) | I46: =SUM(I47:I56) | J46: =SUM(J47:J56) | K46: =SUM(K47:K56) | L46: =SUM(L47:L56) | M46: =SUM(M47:M56) | ... DB46: =SUM(DB47:DB56) | DD46: =SUM(F46:DB46)
B47: ='Economic Assumptions'!$A$10 | D47: =DD47 | F47: =IF('Economic Assumptions'!$B10+'Project Assumptions'!$D$15+'Project Assumptions'!$D$16-1='Detailed Cashflows'!F$5,-'Economic Assumptions'!$C10*'Economic Assumptions'!$L10,0) | G47: =IF('Economic Assumptions'!$B10+'Project Assumptions'!$D$15+'Project Assumptions'!$D$16-1='Detailed Cashflows'!G$5,-'Economic Assumptions'!$C10*'Economic Assumptions'!$L10,0) | H47: =IF('Economic Assumptions'!$B10+'Project Assumptions'!$D$15+'Project Assumptions'!$D$16-1='Detailed Cashflows'!H$5,-'Economic Assumptions'!$C10*'Economic Assumptions'!$L10,0) | I47: =IF('Economic Assumptions'!$B10+'Project Assumptions'!$D$15+'Project Assumptions'!$D$16-1='Detailed Cashflows'!I$5,-'Economic Assumptions'!$C10*'Economic Assumptions'!$L10,0) | J47: =IF('Economic Assumptions'!$B10+'Project Assumptions'!$D$15+'Project Assumptions'!$D$16-1='Detailed Cashflows'!J$5,-'Economic Assumptions'!$C10*'Economic Assumptions'!$L10,0) | K47: =IF('Economic Assumptions'!$B10+'Project Assumptions'!$D$15+'Project Assumptions'!$D$16-1='Detailed Cashflows'!K$5,-'Economic Assumptions'!$C10*'Economic Assumptions'!$L10,0) | L47: =IF('Economic Assumptions'!$B10+'Project Assumptions'!$D$15+'Project Assumptions'!$D$16-1='Detailed Cashflows'!L$5,-'Economic Assumptions'!$C10*'Economic Assumptions'!$L10,0) | M47: =IF('Economic Assumptions'!$B10+'Project Assumptions'!$D$15+'Project Assumptions'!$D$16-1='Detailed Cashflows'!M$5,-'Economic Assumptions'!$C10*'Economic Assumptions'!$L10,0) | ... DB47: =IF('Economic Assumptions'!$B10+'Project Assumptions'!$D$15+'Project Assumptions'!$D$16-1='Detailed Cashflows'!DB$5,-'Economic Assumptions'!$C10*'Economic Assumptions'!$L10,0) | DD47: =SUM(F47:DB47)
...

Sheet Summary Budget
A1: ='Project Assumptions'!A5
A2: Summary Budget
A4: Rentable Square Feet: | C4: ='Project Assumptions'!E11
F6: Total | H6: Per RSF
A8: Land Purchase | F8: ='Detailed Project Costs'!F80 | H8: =F8/$C$4
A10: Land Development and Site Work | F10: ='Detailed Project Costs'!F83 | H10: =F10/$C$4
A12: Building Shell | F12: ='Detailed Project Costs'!F84 | H12: =F12/$C$4
A14: Tenant Improvements (Hard & Soft) | F14: ='Detailed Project Costs'!F85+'Detailed Project Costs'!F90 | H14: =F14/$C$4
A16: Arch. & Eng. and Other Consultants | F16: ='Detailed Project Costs'!F91 | H16: =F16/$C$4
A18: Legal, Marketing, Insurance, Taxes | F18: ='Detailed Project Costs'!F92 | H18: =F18/$C$4
A20: Permits, Testing/Inspection, Fees, Bonds | F20: ='Detailed Project Costs'!F93 | H20: =F20/$C$4
A22: Leasing Commissions | F22: ='Detailed Project Costs'!F94 | H22: =F22/$C$4
A24: Development Fee | F24: ='Detailed Project Costs'!F95 | H24: =F24/$C$4
A26: Finance Fees | F26: ='Detailed Project Costs'!F99 | H26: =F26/$C$4
A28: Interest / Loss to Breakeven | F28: ='Detailed Project Costs'!F100 | H28: =F28/$C$4
A30: Contingency | F30: ='Detailed Project Costs'!F103 | H30: =F30/$C$4
A32: Furniture and Equipment | F32: ='Detailed Project Costs'!F86 | H32: =F32/$C$4
A35: Total Cost Budget | F35: =SUM(F8:F32) | H35: =F35/$C$4
A37: Operating Budget
A39: Rental Income | F39: ='Project Returns'!G15 | H39: =F39/$C$4
A41: Parking Income | F41: ='Project Returns'!G16 | H41: =F41/$C$4
A43: Vacancy | F43: ='Project Returns'!G17 | H43: =F43/$C$4
A45: Structural Reserve | F45: ='Project Returns'!G18 | H45: =F45/$C$4
A47: Operating Expenses | F47: ='Project Returns'!G19 | H47: =F47/$C$4
A49: Net Operating Income | F49: =F39+F41+F43+F45+F47 | H49: =F49/$C$4
A52: Project Yield | F52: =F49/F35
D56: Cap Rate | F56: 0.065
D57: Dev Spread | F57: 0.025
D59: Required Yield | F59: =F57+F56
D61: Gap | F61: =F52-F59

Sheet Lease 1
AN1: =SUM(#REF!) | AO1: =SUM(#REF!) | AP1: =SUM(#REF!)
B4: Tenant | D4: Total RSF | E4: Rental Rate | G4: OPEX | H4: Gross Rent | I4: Term | J4: Escalation
B5: ='Economic Assumptions'!A10 | D5: ='Economic Assumptions'!C10 | E5: ='Economic Assumptions'!D10 | G5: ='Economic Assumptions'!$G$32 | H5: =SUM(E5:G5)
C7: Gross Rent PSF | D7: $/Month | E7: Total
B8: 1 | C8: =IF($B8=1, $H5, IF($B8<=$I5, J5*(1+$J5), 0)) | D8: =E8/12 | E8: =C8*$D$5 | H8: (Years 1-10) | J8: =SUM(C8:C17)
B9: 2 | C9: =IF($B9=1, $H$5, IF($B9<=$I$5, C8*(1+$J$5), 0)) | D9: =E9/12 | E9: =C9*$D$5 | H9: (Years 11-15) | J9: =SUM(C18:C22)
B10: 3 | C10: =IF($B10=1, $H$5, IF($B10<=$I$5, C9*(1+$J$5), 0)) | D10: =E10/12 | E10: =C10*$D$5 | H10: (Years 1-15) | J10: =J8+J9
B11: 4 | C11: =IF($B11=1, $H$5, IF($B11<=$I$5, C10*(1+$J$5), 0)) | D11: =E11/12 | E11: =C11*$D$5
B12: 5 | C12: =IF($B12=1, $H$5, IF($B12<=$I$5, C11*(1+$J$5), 0)) | D12: =E12/12 | E12: =C12*$D$5 | H12: ATL Market LC's
B13: 6 | C13: =IF($B13=1, $H$5, IF($B13<=$I$5, C12*(1+$J$5), 0)) | D13: =E13/12 | E13: =C13*$D$5 | H13: TR | I13: LL | J13: TR + LL
B14: 7 | C14: =IF($B14=1, $H$5, IF($B14<=$I$5, C13*(1+$J$5), 0)) | D14: =E14/12 | E14: =C14*$D$5 | G14: Commission % 1-10 | J14: =SUM(H14:I14)
B15: 8 | C15: =IF($B15=1, $H$5, IF($B15<=$I$5, C14*(1+$J$5), 0)) | D15: =E15/12 | E15: =C15*$D$5 | G15: Commission % 11+ | J15: =SUM(H15:I15)
B16: 9 | C16: =IF($B16=1, $H$5, IF($B16<=$I$5, C15*(1+$J$5), 0)) | D16: =E16/12 | E16: =C16*$D$5
B17: 10 | C17: =IF($B17=1, $H$5, IF($B17<=$I$5, C16*(1+$J$5), 0)) | D17: =E17/12 | E17: =C17*$D$5 | G17: Lease Commissions | H17: =IF(J9=0,J8*$H$14,((J8-H19)*$H$14+J9*$H$15)) | I17: =IF(J9=0,J8*$I$14,((J8-I19)*$I$14+J9*$I$15)) | J17: =H17+I17
B18: 11 | C18: =IF($B18=1, $H$5, IF($B18<=$I$5, C17*(1+$J$5), 0)) | D18: =E18/12 | E18: =C18*$D$5
B19: 12 | C19: =IF($B19=1, $H$5, IF($B19<=$I$5, C18*(1+$J$5), 0)) | D19: =E19/12 | E19: =C19*$D$5 | G19: Pro Fee | H19: =J19 | I19: =J19*0.5 | J19: =C8/12
B20: 13 | C20: =IF($B20=1, $H$5, IF($B20<=$I$5, C19*(1+$J$5), 0)) | D20: =E20/12 | E20: =C20*$D$5 | G20: (1st month's rent) | H20: =H17+H19 | I20: =I17+I19 | J20: =SUM(H20:I20)
B21: 14 | C21: =IF($B21=1, $H$5, IF($B21<=$I$5, C20*(1+$J$5), 0)) | D21: =E21/12 | E21: =C21*$D$5
B22: 15 | C22: =IF($B22=1, $H$5, IF($B22<=$I$5, C21*(1+$J$5), 0)) | D22: =E22/12 | E22: =C22*$D$5 | G22: TOTALS | H22: =H20*'Economic Assumptions'!C10 | I22: =I20*'Economic Assumptions'!C10 | J22: =J20*'Economic Assumptions'!C10
H23: Total TR | I23: Total LL | J23: TOTAL

Sheet Lease 2
AN1: =SUM(#REF!) | AO1: =SUM(#REF!) | AP1: =SUM(#REF!)
B4: Tenant | D4: Total RSF | E4: Rental Rate | G4: OPEX | H4: Gross Rent | I4: Term | J4: Escalation
B5: ='Economic Assumptions'!A11 | D5: ='Economic Assumptions'!C11 | E5: ='Economic Assumptions'!D11 | G5: ='Economic Assumptions'!$G$32 | H5: =SUM(E5:G5)
C7: Gross Rent PSF | D7: $/Month | E7: Total
B8: 1 | C8: =IF($B8=1, $H5, IF($B8<=$I5, J5*(1+$J5), 0)) | D8: =E8/12 | E8: =C8*$D$5 | H8: (Years 1-10) | J8: =SUM(C8:C17)
B9: 2 | C9: =IF($B9=1, $H$5, IF($B9<=$I$5, C8*(1+$J$5), 0)) | D9: =E9/12 | E9: =C9*$D$5 | H9: (Years 11-15) | J9: =SUM(C18:C22)
B10: 3 | C10: =IF($B10=1, $H$5, IF($B10<=$I$5, C9*(1+$J$5), 0)) | D10: =E10/12 | E10: =C10*$D$5 | H10: (TOTAL) | J10: =J8+J9
B11: 4 | C11: =IF($B11=1, $H$5, IF($B11<=$I$5, C10*(1+$J$5), 0)) | D11: =E11/12 | E11: =C11*$D$5
B12: 5 | C12: =IF($B12=1, $H$5, IF($B12<=$I$5, C11*(1+$J$5), 0)) | D12: =E12/12 | E12: =C12*$D$5 | H12: ATL Market LC's
B13: 6 | C13: =IF($B13=1, $H$5, IF($B13<=$I$5, C12*(1+$J$5), 0)) | D13: =E13/12 | E13: =C13*$D$5 | H13: TR | I13: LL | J13: TR + LL
